Workbook

Sheet BALANCE_MAYO_2026
D1: INGRESOS | AI1: PROYECTO CORPORACION
C2: INGRESO BAÑOS | G2: INGRESO SAYAUSI | I2: SR. NORMA | N2: Gastos OPSATEL | S2: ANALISIS | T2: DE CUENTAS | U2: OPSATEL | V2: Lab dBLog | Z2: GASTOS PLATAFORMA | AH2: OPSATEL dBLog
A3: COD-CLI | B3: FECHA DE PAGO | C3: Tipo Efectivo/Transferencia | D3: VALOR | E3: COD-CLI | F3: FECHA DE PAGO | G3: Tipo Efectivo/Transferencia | H3: Fecha Colaborador | I3: N° Comp Depósito | J3: VALOR | M3: item | N3: Descripción | O3: fecha | P3: Tipo Efectivo/Transferencia | Q3: valor | T3: SOBRANTE ANTERIOR MES | U3: OPSATEL | V3: Lab dBLog | W3: Pichincha | Z3: item | AA3: Descripcion | AC3: Fecha | AD3: Tipo Efectivo/Transferencia | AE3: valor | AH3: item | AI3: Descripcion | AK3: Fecha | AL3: Tipo Efectivo/Transferencia | AM3: valor
L4: VARIOS | M4: 1 | T4: CAJA CHICA | Y4: GASTOS VARIOS | Z4: 1 | AA4: CLARO PLAN CELU TEC ADMIN | AB4: COTITULARES | AC4: 45389 | AH4: 1 | AI4: WILIAM SANANGO | AK4: 45743
M5: 2 | T5: PICHINCHA | W5: PLUS | Z5: 2 | AH5: 2 | AI5: INTERESES CUENTA | AK5: 45743
M6: 3 | T6: JEP | W6: Proyectos | Z6: 3 | AA6: PLATAFORMA EXT | AB6: PERSONAL | AC6: 45769 | AH6: 1 | AI6: WILIAM SANANGO | AK6: 45791
M7: 4 | T7: SUBTOTAL | Z7: 4 | AA7: DiGITAL OCEAN OPSATEL | AB7: PERSONAL | AC7: 45748 | AH7: 2 | AI7: ELECAUSTRO CAMISAS | AK7: 45792
M8: 5 | T8: RESERVA | Z8: 5 | AA8: GOOGLE ONE DRIVE | AB8: PERSONAL | AC8: 45758 | AH8: 3 | AI8: PROYECTO AG CONSTRUCCIONES | AK8: 45874
M9: 6 | T9: TOTAL | Z9: 6 | AA9: ZAPING SPORTS | AB9: PERSONAL | AC9: 45749 | AH9: 4 | AI9: PROYECTO CLASES SUDAMERICANO | AK9: 45888
M10: 3 | T10: OPSATEL | V10: Lab dBLog | Z10: 7 | AA10: SMARTONE SR. AYALA | AB10: PERSONAL | AC10: 45706 | AH10: 5 | AI10: AYUDA OPSATEL | AK10: 45930
M11: 4 | S11: Caja CHICA | T11: =D19+D22+J19+J22+H38+U4-Q128 -> 254.85 | Z11: 8 | AA11: VPS | AB11: PERSONAL | AC11: 45997 | AH11: 6
M12: 5 | S12: PICHINCHA | T12: =D20+D23+J20+J23+H39+U5-Q129 -> 304.47 | V12: =AB46 -> 27.16 | AH12: 7 | AI12: WILIAM SANANGO | AK12: 45915
M13: 6 | S13: JEP | T13: =D21+D24+J21+J24+H40+U6+AE48-Q130 -> 165.14 | AH13: 8
M14: 7 | AL14: Pichincha | AM14: =SUMIF(AL4:AL13,"Pichincha",AM4:AM13) -> 0
M15: 8 | AG15: GASTOS GENERAL
M16: 9
M17: 10 | S17: TOTAL | T17: =SUM(T11:T13)+V12+V11 -> 751.62 | U17: =SUM(U11:U13)+W12+W11 -> 0 | Z17: 14 | AH17: item | AI17: Descripcion | AK17: Fecha | AL17: Tipo Efectivo/Transferencia | AM17: valor
M18: 11 | S18: CUENTA AUXILIAR | Z18: 15 | AG18: TECNICO | AH18: 1
C19: Efectivo | D19: =SUMIF(BAÑOS!BP2:BP270,C19,BAÑOS!BO2:BO270)+SUMIF(C4:C18,C19,D4:D18) -> 254.85 | F19: MOVIMIENTOS INTERNOS INGRESOS | I19: Efectivo | J19: =SUMIF(SAYAUSI!BP2:BP175,I19,SAYAUSI!BO2:BO175)+SUMIF(G4:G18,I19,J4:J18) -> 0 | M19: 12 | S19: SALDO DISPONIBLE | T19: =T17+V17 -> 751.62 | AD19: Efectivo | AE19: =SUMIF($AD$4:$AD$18,"Efectivo",$AE$4:AE18) -> 0 | AH19: 2
C20: Pichincha | D20: =SUMIF(BAÑOS!BP2:BP270,C20,BAÑOS!BO2:BO270)+SUMIF(C4:C18,C20,D4:D18) -> 248.43 | E20: DE | F20: FECHA DE PAGO | G20: Tipo Efectivo/Transferencia | H20: VALOR | I20: Pichincha | J20: =SUMIF(SAYAUSI!BP2:BP175,I20,SAYAUSI!BO2:BO175)+SUMIF(G4:G18,I20,J4:J18) -> 56.04 | M20: 13 | T20: RESERVA PICHINCHA CLIENTES | AD20: Pichincha | AE20: =SUMIF($AD$4:$AD$18,"Pichincha",$AE$4:AE19) -> 0 | AH20: 3
C21: JEP | D21: =SUMIF(BAÑOS!BP2:BP270,C21,BAÑOS!BO2:BO270)+SUMIF(C4:C18,C21,D4:D18) -> 68.54 | I21: JEP | J21: =SUMIF(SAYAUSI!BP2:BP175,I21,SAYAUSI!BO2:BO175)+SUMIF(G4:G18,I21,J4:J18) -> 84.6 | M21: 14 | T21: RESERVA EFECTIVO CLIENTES | AD21: JEP | AE21: =SUMIF($AD$4:$AD$18,"JEP",$AE$4:AE20) -> 0 | AH21: 4
C22: Extra Efectivo | D22: =SUMIF(BAÑOS!BP2:BP270,C22,BAÑOS!BO2:BO270)+SUMIF(C4:C18,C22,D4:D18) -> 0 | I22: Extra Efectivo | J22: =SUMIF(SAYAUSI!BP2:BP175,I22,SAYAUSI!BO2:BO175)+SUMIF(G4:G18,I22,J4:J18) -> 0 | M22: 1 | AH22: 5
C23: Extra Pichincha | D23: =SUMIF(BAÑOS!BP2:BP270,C23,BAÑOS!BO2:BO270)+SUMIF(C4:C18,C23,D4:D18) -> 0 | I23: Extra Pichincha | J23: =SUMIF(SAYAUSI!BP2:BP175,I23,SAYAUSI!BO2:BO175)+SUMIF(G4:G18,I23,J4:J18) -> 0 | M23: 2 | T23: RECAUDAR | U23: CLIENTES | V23: RECAUDADO | W23: CARTERA X VENCER | AA23: MOVIMIENTOS INTERNOS | AH23: 6
C24: Extra JEP | D24: =SUMIF(BAÑOS!BP2:BP270,C24,BAÑOS!BO2:BO270)+SUMIF(C4:C18,C24,D4:D18) -> 0 | I24: Extra JEP | J24: =SUMIF(SAYAUSI!BP2:BP175,I24,SAYAUSI!BO2:BO175)+SUMIF(G4:G18,I24,J4:J18) -> 0 | M24: 3 | S24: BAÑOS TOTAL | T24: =SUM(BAÑOS!IY2:IY207)+SUM(BAÑOS!JA2:JA207)+SUM(BAÑOS!JB2:JB207) -> 0 | U24: =COUNTIF(BAÑOS!JA2:JA207,"<>") -> 0 | V24: =SUM(BAÑOS!HQ2:HQ185)+SUM(BAÑOS!HS2:HS185) -> 0 | W24: =SUMIF(BAÑOS!HR2:HR185,"",BAÑOS!HU6:HU185) -> 0 | Z24: item | AA24: BANK | AC24: Fecha | AD24: BANK | AE24: valor | AH24: 7
C25: Reserva Pichincha | D25: =SUMIF(BAÑOS!BP2:BP270,C25,BAÑOS!BO2:BO270)+SUMIF(C4:C18,C25,D4:D18) -> 0 | I25: Reserva Pichincha | J25: =SUMIF(SAYAUSI!BP2:BP175,I25,SAYAUSI!BO2:BO175)+SUMIF(G4:G18,I25,J4:J18) -> 0 | L25: SUDA | M25: 1 | S25: SAYAUSI TOTAL | T25: =SUM(SAYAUSI!JR2:JR115)+SUM(SAYAUSI!JT2:JT115)+SUM(SAYAUSI!JU2:JU115) -> 0 | U25: =COUNTIF(SAYAUSI!JT2:JT115,"<>") -> 0 | V25: =SUM(SAYAUSI!ID2:ID109)+SUM(SAYAUSI!IG2:IG109) -> 0 | W25: =SUMIF(SAYAUSI!ID2:ID109,"",SAYAUSI!II2:II109) -> 0 | Y25: TRANSF EGRESOS | Z25: 1 | AH25: 8
C26: Reserva Efectivo | D26: =SUMIF(BAÑOS!BP2:BP270,C26,BAÑOS!BO2:BO270)+SUMIF(C4:C18,C26,D4:D18) -> 0 | I26: Reserva Efectivo | J26: =SUMIF(SAYAUSI!BP2:BP175,I26,SAYAUSI!BO2:BO175)+SUMIF(G4:G18,I26,J4:J18) -> 0 | M26: 2 | S26: PREPAGO | T26: =SUM(D4:D18)+SUM(J4:J18) -> 0 | Z26: 2 | AH26: 9
C27: TOTAL | D27: =SUM(D19:D26) -> 571.82 | I27: TOTAL | J27: =SUM(J19:J26) -> 140.64 | M27: 3 | S27: dBLog PLUS | T27: =SUM(PLATAFORMA!BK2:BK38) -> 0 | Z27: 3 | AH27: 10
L28: HELP PROYECTO | M28: 1 | Z28: 4 | AH28: 11
M29: 2 | Z29: 5 | AH29: 12
M30: 3 | S30: TOTAL | T30: =SUM(T24:T29) -> 0 | U30: =SUM(U24:U25) -> 0 | Z30: 6 | AH30: 13
L31: INVERSION CLIENTES NUEVOS | M31: 1 | S31: GASTOS | T31: =SUM(Q4:Q100)+SUM(AE4:AE18) -> 4674.45 | Z31: 7 | AH31: 14
M32: 2 | Z32: 8 | AH32: 15
M33: 1 | S33: A FAVOR OPSATEL | T33: =T30-T31 -> -4674.45 | Z33: 9 | AH33: 16
M34: 2 | Y34: TRANSF INGRESOS | Z34: 1 | AH34: 1
M35: 3 | Z35: 2 | AH35: 2
M36: 4 | T36: LIMA | U36: LLERENA | V36: SOLANO | W36: PAUL | Z36: 3 | AH36: 3
M37: 5 | S37: ADELANTO1 | W37: 2.75 | Z37: 4 | AH37: 4
G38: Efectivo | H38: =SUMIF(G21:G37,"Efectivo",H21:H37) -> 0 | M38: 6 | S38: OPSATEL | Z38: 5 | AH38: 5
G39: Trans Pichincha | H39: =SUMIF(G21:G37,"Pichincha",H21:H37) -> 0 | M39: 7 | S39: ENTREGADO | Z39: 6 | AH39: 6
G40: Trans JEP | H40: =SUMIF(G21:G37,"JEP",H21:H37) -> 0 | L40: PRESTAMOS | M40: 1 | S40: ADELANTO 1 | AD40: Efectivo EGRESOS | AE40: =SUMIF($AD$25:$AD$33,"Efectivo",$AE$25:$AE$33) -> 0 | AH40: 1
...

Sheet BAÑOS
B1: NAME | C1: IP | D1: ESTADO | E1: CED | F1: TIEMPO (MESES) | G1: DOCUMENTS | H1: PARISH | I1: RENT | J1: DIRECTION | K1: MAIL | L1: CEL | M1: CUENTA | N1: INSTALATION DATE | O1: PLAN | P1: INS_PAYMENT | Q1: SALDO | R1: FACT DIC | S1: INTERNET PAYMENT | T1: APP | U1: PAYMENT DATE | V1: CLIENT PAYMENT DATE | W1: INTERNET PAYMENT | X1: BANK | Y1: COD | Z1: PLUS | AA1: BANK_PLUS | AB1: SALDO | AC1: FACT JANUARY | AD1: INTERNET PAYMENT | AE1: APP | AF1: PAYMENT DATE | AG1: CLIENT PAYMENT DATE | AH1: INTERNET PAYMENT | AI1: BANK | AJ1: COD | AK1: PLUS | AL1: BANK_PLUS | AM1: SALDO | AN1: FACTURAS | AO1: INTERNET PAYMENT | AP1: APP | AQ1: PAYMENT DATE | AR1: CLIENT PAYMENT DATE | AS1: INTERNET PAYMENT | AT1: BANK | AU1: COD | AV1: PLUS | AW1: BANK_PLUS | AX1: SALDO | AY1: FACTURAS | AZ1: INTERNET PAYMENT | BA1: APP | BB1: PAYMENT DATE | BC1: CLIENT PAYMENT DATE | BD1: INTERNET PAYMENT | BE1: BANK | BF1: COD | BG1: PLUS | BH1: BANK_PLUS | BI1: SALDO | BJ1: FACTURAS | BK1: INTERNET PAYMENT | BL1: APP | BM1: PAYMENT DATE | BN1: CLIENT PAYMENT DATE | BO1: INTERNET PAYMENT | BP1: BANK | BQ1: COD | BR1: PLUS | BS1: BANK_PLUS | BT1: SALDO | BU1: FACTURAS
A2: =IFERROR(__xludf.DUMMYFUNCTION("IMPORTRANGE(""https://https://docs.google.com/spreadsheets/d/1GLbJTdVpWS8XRg8Za_otK8cqLfTYxobGAYdYQwJylW8/edit?gid=0#gid=0"", ""MAIN!B2"")"),"C01") -> C01 | B2: SAMANIEGO FEIJO ANDREA BELEN | C2: 172.17.2.2 | D2: ACTIVO | E2: F | F2: 18 | G2: 0105504971 | H2: EL SAGRARIO | I2: NO | J2: RAFAEL MARI ARIZAGA Y VARGAS MACHUCA | K2: beley18@hotmail.com | L2: 0986944564 | N2: 45086 | O2: 650M/650M | Q2: 0 | R2: C02245 | S2: 23 | T2: 0 | U2: 46036 | AB2: =Q2+S2+T2-W2-Z2 -> 23 | AC2: C02352 | AD2: 23 | AE2: 0 | AF2: 46067 | AG2: 46078 | AH2: 46 | AI2: Pichincha | AM2: =(AB2+AD2+AE2)-(AH2+AK2) -> 0 | AN2: SIN FACTURA | AO2: 23 | AP2: 0 | AQ2: 46095 | AR2: 26/3/2026 | AS2: 23 | AT2: Pichincha | AX2: =(AM2+AO2+AP2)-(AS2+AV2) -> 0 | AY2: SIN FACTURA | AZ2: 23 | BA2: 0 | BB2: 46126 | BC2: 16/4/2026 | BD2: 23 | BE2: Pichincha | BI2: =(AX2+AZ2+BA2)-(BD2+BG2) -> 0 | BK2: 23 | BL2: 0 | BM2: 46156 | BT2: =(BI2+BK2+BL2)-(BO2+BR2) -> 23
A3: =IFERROR(__xludf.DUMMYFUNCTION("IMPORTRANGE(""https://https://docs.google.com/spreadsheets/d/1GLbJTdVpWS8XRg8Za_otK8cqLfTYxobGAYdYQwJylW8/edit?gid=0#gid=0"", ""MAIN!B3"")"),"C02") -> C02 | B3: HERNANDEZ SALAS NORA GABRIELA | C3: 10.65.4.4:5151 | D3: ACTIVO | E3: F | F3: 20 | G3: 1715444947 | H3: EL SAGRARIO | I3: SI | J3: RAFAEL MARI ARIZAGA Y VARGAS MACHUCA | K3: norahs1980@hotmail.com | L3: 0994089449 0963182639 | O3: 650M/650M | Q3: 0 | S3: 23 | T3: 0 | U3: 46036 | V3: 46044 | W3: 23 | X3: Pichincha | AB3: =Q3+S3+T3-W3-Z3 -> 0 | AC3: SIN FACTURA | AD3: 23 | AE3: 0 | AF3: 46067 | AG3: 46073 | AH3: 23 | AI3: Pichincha | AM3: =(AB3+AD3+AE3)-(AH3+AK3) -> 0 | AN3: SIN FACTURA | AO3: 23 | AP3: 0 | AQ3: 46095 | AR3: 46100 | AS3: 23 | AT3: Pichincha | AX3: =(AM3+AO3+AP3)-(AS3+AV3) -> 0 | AY3: SIN FACTURA | AZ3: 23 | BA3: 0 | BB3: 46126 | BC3: 28/4/2026 | BD3: 23 | BE3: Pichincha | BI3: =(AX3+AZ3+BA3)-(BD3+BG3) -> 0 | BK3: 23 | BL3: 0 | BM3: 46156 | BT3: =(BI3+BK3+BL3)-(BO3+BR3) -> 23
A4: =IFERROR(__xludf.DUMMYFUNCTION("IMPORTRANGE(""https://https://docs.google.com/spreadsheets/d/1GLbJTdVpWS8XRg8Za_otK8cqLfTYxobGAYdYQwJylW8/edit?gid=0#gid=0"", ""MAIN!B4"")"),"C03") -> C03 | B4: GUTIERREZ ARIAS JOSE ROLANDO | C4: 172.17.1.3 | D4: ACTIVO | E4: M | F4: 24 | G4: 0100758994 | H4: EL SAGRARIO | I4: SI | J4: RAFAEL MARI ARIZAGA Y MARIANO CUEVA | L4: 0992257063 | M4: 199cejoseg | N4: 45743 | O4: 100M/100M | Q4: -0.5 | S4: 17.25 | T4: 0 | U4: 46032 | V4: 46049 | W4: 17 | X4: Pichincha | AB4: =Q4+S4+T4-W4-Z4 -> -0.25 | AC4: SIN FACTURA | AD4: 17.25 | AE4: 0 | AF4: 46063 | AG4: 46080 | AH4: 17.25 | AI4: Pichincha | AM4: =(AB4+AD4+AE4)-(AH4+AK4) -> -0.25 | AN4: SIN FACTURA | AO4: 17.25 | AP4: 0 | AQ4: 46091 | AR4: 9/3/2026 | AS4: 17.25 | AT4: Pichincha | AX4: =(AM4+AO4+AP4)-(AS4+AV4) -> -0.25 | AY4: SIN FACTURA | AZ4: 17.25 | BA4: 0 | BB4: 46122 | BC4: 11/4/2026 | BD4: 17.25 | BE4: Pichincha | BI4: =(AX4+AZ4+BA4)-(BD4+BG4) -> -0.25 | BK4: 17.25 | BL4: 0 | BM4: 46152 | BT4: =(BI4+BK4+BL4)-(BO4+BR4) -> 17
A5: =IFERROR(__xludf.DUMMYFUNCTION("IMPORTRANGE(""https://https://docs.google.com/spreadsheets/d/1GLbJTdVpWS8XRg8Za_otK8cqLfTYxobGAYdYQwJylW8/edit?gid=0#gid=0"", ""MAIN!B5"")"),"C04") -> C04 | B5: MARQUEZ MARQUEZ ROSA CARMELA | C5: 172.17.1.2 | D5: ACTIVO | E5: F | G5: 0703952135 | H5: BAÑOS | I5: SI | J5: VIA MINAS | K5: rosacarmelamarquezmarquez@gmail.com | L5: 0995398106 | N5: 45209 | O5: 650M/650M | P5: GRATIS | Q5: 0 | R5: C02246 | S5: 23 | T5: 0 | U5: 46032 | V5: 46032 | W5: 23 | X5: JEP | AB5: =Q5+S5+T5-W5-Z5 -> 0 | AC5: C02353 | AD5: 23 | AE5: 0 | AF5: 46063 | AG5: 46060.415 | AH5: 23 | AI5: JEP | AM5: =(AB5+AD5+AE5)-(AH5+AK5) -> 0 | AN5: C02456 | AO5: 23 | AP5: 0 | AQ5: 46091 | AR5: 9/3/2026 | AS5: 23 | AT5: JEP | AX5: =(AM5+AO5+AP5)-(AS5+AV5) -> 0 | AY5: C02574 | AZ5: =23+15 -> 38 | BA5: 0 | BB5: 46122 | BC5: 7/4/2026 | BD5: =23+15 -> 38 | BE5: JEP | BI5: =(AX5+AZ5+BA5)-(BD5+BG5) -> 0 | BK5: =23+15 -> 38 | BL5: 0 | BM5: 46152 | BT5: =(BI5+BK5+BL5)-(BO5+BR5) -> 38
A6: 002 | B6: MACAS NAMCELA MARIA MERCEDES | C6: 172.16.0.3 | D6: INACTIVO | G6: 1103427447 | H6: BAÑOS | I6: SI | J6: SECTOR EL CHORRO CALLE GUADALUPANA | K6: rosamarianamacasnamcela@gmail.com | L6: 0986347428 0967759439 0985702275 | N6: 44347 | O6: 100M/100M | P6: 37 | Q6: 0 | T6: 0 | AB6: =Q6+S6+T6-W6-Z6 -> 0 | AC6: SIN FACTURA | AE6: 0 | AM6: =(AB6+AD6+AE6)-(AH6+AK6) -> 0 | AN6: SIN FACTURA | AP6: 0 | AX6: =(AM6+AO6+AP6)-(AS6+AV6) -> 0 | AY6: SIN FACTURA | BA6: 0 | BI6: =(AX6+AZ6+BA6)-(BD6+BG6) -> 0 | BL6: 0 | BT6: =(BI6+BK6+BL6)-(BO6+BR6) -> 0
A7: 003 | B7: CASTILLO GUAMAN MIRIAM PATRICIA | C7: 172.16.1.2 | D7: ACTIVO | E7: F | G7: 0103832432 | H7: BAÑOS | I7: NO | J7: AV. RICARDO DURAN Y CALLE LA CALIZA (ESQUINA) | K7: miacastillo27@hotmail.com | L7: 0992296564 0929902571 | M7: 03bamiriamc | N7: 44348 | O7: 100M/100M | P7: 37 | Q7: 0 | R7: C02247 | S7: 23 | T7: 0 | U7: 46036 | V7: 46037 | W7: 23 | X7: Efectivo | AB7: =Q7+S7+T7-W7-Z7 -> 0 | AC7: C02354 | AD7: 23 | AE7: 0 | AF7: 46067 | AG7: 46073.687 | AH7: 23 | AI7: Efectivo | AM7: =(AB7+AD7+AE7)-(AH7+AK7) -> 0 | AN7: C02457 | AO7: 23 | AP7: 0 | AQ7: 46095 | AR7: 19/3/2026 | AS7: 23 | AT7: Efectivo | AX7: =(AM7+AO7+AP7)-(AS7+AV7) -> 0 | AY7: C02575 | AZ7: 23 | BA7: 0 | BB7: 46126 | BC7: 16/4/2026 | BD7: 23 | BE7: Efectivo | BI7: =(AX7+AZ7+BA7)-(BD7+BG7) -> 0 | BJ7: C02687 | BK7: 23 | BL7: 0 | BM7: 46156 | BT7: =(BI7+BK7+BL7)-(BO7+BR7) -> 23
A8: 004 | B8: CURIPOMA MEJICANO LORGIA | C8: 172.16.0.4 | D8: INACTIVO | E8: F | G8: 1715117121 | H8: YANUNCAY | I8: NO | J8: YANUNCAY | K8: curipomalorgia77@gmail.com | L8: 0999463238 0994616304 | M8: 4bacuripomal | N8: 44349 | O8: 650M/650M | P8: 37 | Q8: 0 | T8: 0 | AB8: =Q8+S8+T8-W8-Z8 -> 0 | AC8: SIN FACTURA | AE8: 0 | AM8: =(AB8+AD8+AE8)-(AH8+AK8) -> 0 | AN8: SIN FACTURA | AP8: 0 | AX8: =(AM8+AO8+AP8)-(AS8+AV8) -> 0 | AY8: SIN FACTURA | BA8: 0 | BI8: =(AX8+AZ8+BA8)-(BD8+BG8) -> 0 | BL8: 0 | BT8: =(BI8+BK8+BL8)-(BO8+BR8) -> 0
A9: 006 | B9: AUCAPIÑA NARVAEZ GLADYS VIRGINIA | C9: 172.16.3.2 | D9: ACTIVO | E9: F | G9: 1722452420 | H9: YANUNCAY | I9: NO | J9: JUEGO DE DAMAS Y TRES EN RAYA | K9: elizabethaucapina4@gmail.com | L9: 0969018149 096293803 | M9: 06bagladysa | N9: 44356 | O9: 650M/650M | P9: 37 | Q9: 0 | R9: C02248 | S9: 23 | T9: 0 | U9: 46031 | V9: 46028 | W9: 23 | X9: JEP | AB9: =Q9+S9+T9-W9-Z9 -> 0 | AC9: C02356 | AD9: 23 | AE9: 0 | AF9: 46062 | AG9: 46061 | AH9: 23 | AI9: JEP | AM9: =(AB9+AD9+AE9)-(AH9+AK9) -> 0 | AN9: C02458 | AO9: 23 | AP9: 0 | AQ9: 46090 | AR9: 8/3/2026 | AS9: 23 | AT9: JEP | AX9: =(AM9+AO9+AP9)-(AS9+AV9) -> 0 | AY9: C02576 | AZ9: 23 | BA9: 0 | BB9: 46121 | BC9: 7/4/2026 | BD9: 23 | BE9: JEP | BI9: =(AX9+AZ9+BA9)-(BD9+BG9) -> 0 | BJ9: C02688 | BK9: 23 | BL9: 0 | BM9: 46151 | BT9: =(BI9+BK9+BL9)-(BO9+BR9) -> 23
A10: 008 | B10: URGILES OTORONGO JUAN CARLOS | C10: 172.16.2.10 | D10: ACTIVO | E10: M | G10: 0105921860 | H10: BAÑOS | I10: NO | J10: PASEO DE LA GUADALUPANA Y CAMINO A NARANCAY ALTO (INTERSECCION) | K10: juanurgiles4@gmail.com | L10: 0992347655 | M10: 08bacarlos | N10: 44363 | O10: 650M/650M | P10: 37 | Q10: 0 | S10: 25 | T10: 2 | U10: 46041 | V10: 46048.731 | W10: 20 | X10: Efectivo | AB10: =Q10+S10+T10-W10-Z10 -> 7 | AC10: SIN FACTURA | AD10: 25 | AE10: 2 | AF10: 46072 | AG10: 46077 | AH10: =20+14 -> 34 | AI10: Efectivo | AM10: =(AB10+AD10+AE10)-(AH10+AK10) -> 0 | AN10: SIN FACTURA | AO10: 25 | AP10: 2 | AQ10: 46100 | AR10: 46107.74 | AS10: 27 | AT10: Efectivo | AX10: =(AM10+AO10+AP10)-(AS10+AV10) -> 0 | AY10: SIN FACTURA | AZ10: 25 | BA10: 2 | BB10: 46131 | BC10: 28/4/2026 | BD10: 23 | BE10: Efectivo | BI10: =(AX10+AZ10+BA10)-(BD10+BG10) -> 4 | BK10: 25 | BL10: 2 | BM10: 46161 | BT10: =(BI10+BK10+BL10)-(BO10+BR10) -> 31
A11: 010 | B11: YUMBLA CHILLOGALLI DIEGO FERNANDO | C11: 172.16.6.6 | D11: ACTIVO | E11: M | G11: 0105541320 | H11: BAÑOS | I11: SI | J11: RICARDO DURAN | K11: diferyumbla@gmail.com | L11: 0995461082 | M11: 010badiegoy | N11: 45548 | O11: 100M/100M | P11: GRATIS | Q11: 0 | R11: C02185 | S11: 17.25 | T11: 2 | U11: 46037 | V11: 46031 | W11: 17.25 | X11: Pichincha | Z11: 2 | AA11: Pichincha | AB11: =Q11+S11+T11-W11-Z11 -> 0 | AC11: SIN FACTURA | AD11: 17.25 | AE11: 2 | AF11: 46068 | AG11: 46076 | AH11: 19.25 | AI11: Pichincha | AM11: =(AB11+AD11+AE11)-(AH11+AK11) -> 0 | AN11: SIN FACTURA | AO11: 17.25 | AP11: 2 | AQ11: 46096 | AR11: 10/3/2026 | AS11: 17.25 | AT11: Pichincha | AV11: 2 | AW11: Pichincha | AX11: =(AM11+AO11+AP11)-(AS11+AV11) -> 0 | AY11: SIN FACTURA | AZ11: 17.25 | BA11: 2 | BB11: 46127 | BC11: 46119.568 | BD11: 17.25 | BE11: Efectivo | BI11: =(AX11+AZ11+BA11)-(BD11+BG11) -> 2 | BK11: 17.25 | BL11: 2 | BM11: 46157 | BT11: =(BI11+BK11+BL11)-(BO11+BR11) -> 21.25
A12: 011 | B12: ORDOÑEZ SIGUA CARMEN LETICIA | C12: 172.16.2.2 | D12: ACTIVO | E12: F | F12: 24 | G12: 0106447535 | H12: BAÑOS | I12: SI | J12: GUADALUPANO ALTO CALLE EL CALVARIO | K12: wpalvarezn@gmail.com | L12: 0995516478 0995183363 | N12: 45666 | O12: 650M/650M | P12: GRATIS | Q12: 0 | R12: C02186 | S12: 17.25 | T12: 0 | U12: 46041 | V12: 46045 | W12: 17.25 | X12: Pichincha | AB12: =Q12+S12+T12-W12-Z12 -> 0 | AC12: C02297 | AD12: 17.25 | AE12: 0 | AF12: 46072 | AG12: 46076 | AH12: 17.25 | AI12: Efectivo | AM12: =(AB12+AD12+AE12)-(AH12+AK12) -> 0 | AN12: C02407 | AO12: 17.25 | AP12: 0 | AQ12: 46100 | AR12: 46107.359 | AS12: 17.25 | AT12: Efectivo | AX12: =(AM12+AO12+AP12)-(AS12+AV12) -> 0 | AY12: C02520 | AZ12: 17.25 | BA12: 0 | BB12: 46131 | BC12: 23/4/2026 | BD12: 17.25 | BE12: Pichincha | BI12: =(AX12+AZ12+BA12)-(BD12+BG12) -> 0 | BJ12: C02634 | BK12: 17.25 | BL12: 0 | BM12: 46161 | BT12: =(BI12+BK12+BL12)-(BO12+BR12) -> 17.25
A13: 012 | B13: ALVAREZ VELECELA KEVIN ALEXANDER | C13: 172.16.2.3 | D13: ACTIVO | E13: F | F13: 24 | G13: 0150675601 | H13: BAÑOS | I13: NO | J13: GUADALUPANO ALTO CALLE EL CALVARIO | K13: ke266@aicloud.com | L13: 0981087927 | N13: 46059 | O13: 100M/100M | P13: GRATIS | Q13: 0 | S13: 20.54 | T13: 0 | U13: 46032 | AB13: =Q13+S13+T13-W13-Z13 -> 20.54 | AC13: C02319 | AD13: 17.25 | AE13: 0 | AF13: 46063 | AG13: 46059 | AH13: =20.54+17.25 -> 37.79 | AI13: Efectivo | AM13: =(AB13+AD13+AE13)-(AH13+AK13) -> 0 | AN13: SIN FACTURA | AO13: 17.25 | AP13: 0 | AQ13: 46091 | AR13: 46105.473 | AS13: 20.54 | AT13: Efectivo | AX13: 0 | AY13: SIN FACTURA | AZ13: 17.25 | BA13: 0 | BB13: 46122 | BC13: 20/04/2026 | BD13: 17.25 | BE13: JEP | BI13: =(AX13+AZ13+BA13)-(BD13+BG13) -> 0 | BK13: 17.25 | BL13: 0 | BM13: 46152 | BT13: =(BI13+BK13+BL13)-(BO13+BR13) -> 17.25
A14: 013 | B14: LOJANO SANCHEZ MARIA ANGELITA | C14: 172.16.2.4 | D14: ACTIVO | E14: F | G14: 0102986619 | H14: BAÑOS | I14: NO | J14: GUADALUPANO ALTO CALLE EL CALVARIO | K14: facturas.labsll@gmail.com | L14: 0968375793 0991434170 0993528296 | N14: 44383 | O14: 100M/100M | P14: GRATIS | Q14: 0 | S14: 17.25 | T14: 0 | U14: 46031 | V14: 46266 | W14: 17.25 | X14: Efectivo | AB14: =Q14+S14+T14-W14-Z14 -> 0 | AC14: SIN FACTURA | AD14: 17.25 | AE14: 0 | AF14: 46062 | AG14: 46064 | AH14: 17.25 | AI14: Efectivo | AM14: =(AB14+AD14+AE14)-(AH14+AK14) -> 0 | AN14: SIN FACTURA | AO14: 17.25 | AP14: 0 | AQ14: 46090 | AR14: 10/3/2026 | AS14: 17.25 | AT14: Efectivo | AX14: =(AM14+AO14+AP14)-(AS14+AV14) -> 0 | AY14: SIN FACTURA | AZ14: 17.25 | BA14: 0 | BB14: 46121 | BC14: 46122.393 | BD14: 17.25 | BE14: Efectivo | BI14: =(AX14+AZ14+BA14)-(BD14+BG14) -> 0 | BK14: 17.25 | BL14: 0 | BM14: 46151 | BT14: =(BI14+BK14+BL14)-(BO14+BR14) -> 17.25
A15: 016 | B15: ORDOÑEZ SIGUA LUIS HIPOLITO | C15: 172.16.2.5 | D15: ACTIVO | E15: M | G15: 0103855920 | H15: BAÑOS | I15: NO | J15: GUADALUPANO ALTO | K15: dianys1895@gmail.com | L15: 0988149915 | N15: 44403 | O15: 650M/650M | P15: GRATIS | Q15: 0 | R15: C02187 | S15: 17.25 | T15: 0 | U15: 46031 | V15: 46035 | W15: 17.25 | X15: Pichincha | AB15: =Q15+S15+T15-W15-Z15 -> 0 | AC15: C02298 | AD15: 17.25 | AE15: 0 | AF15: 46062 | AG15: 46072 | AH15: 17.25 | AI15: Pichincha | AM15: =(AB15+AD15+AE15)-(AH15+AK15) -> 0 | AN15: C02408 | AO15: 17.25 | AP15: 0 | AQ15: 46090 | AR15: 17/03/2026 | AS15: 17.25 | AT15: Pichincha | AX15: =(AM15+AO15+AP15)-(AS15+AV15) -> 0 | AY15: C02521 | AZ15: 17.25 | BA15: 0 | BB15: 46121 | BC15: 7/4/2026 | BD15: 17.25 | BE15: Pichincha | BI15: =(AX15+AZ15+BA15)-(BD15+BG15) -> 0 | BJ15: C02635 | BK15: 17.25 | BL15: 0 | BM15: 46151 | BT15: =(BI15+BK15+BL15)-(BO15+BR15) -> 17.25
A16: 019 | B16: CASTILLO MONTALEZA MANUEL SANTOS | C16: 172.16.1.6 | D16: ACTIVO | E16: M | G16: 0101565398 | H16: BAÑOS | I16: NO | J16: CALLE LA CALIZA Y RICARDO DURAN | K16: manuelscastillom@gmail.com | L16: 0997876310 0992909166 | N16: 44424 | O16: 100M/100M | P16: GRATIS | Q16: 0 | R16: C02188 | S16: 17.25 | T16: 0 | U16: 46031 | V16: 46037 | W16: 17.25 | X16: Efectivo | AB16: =Q16+S16+T16-W16-Z16 -> 0 | AC16: C02299 | AD16: 17.25 | AE16: 0 | AF16: 46062 | AH16: 17.25 | AI16: Efectivo | AM16: =(AB16+AD16+AE16)-(AH16+AK16) -> 0 | AN16: C02409 | AO16: 17.25 | AP16: 0 | AQ16: 46090 | AR16: 16/3/2026 | AS16: 17.25 | AT16: Efectivo | AX16: =(AM16+AO16+AP16)-(AS16+AV16) -> 0 | AY16: C02522 | AZ16: 17.25 | BA16: 0 | BB16: 46121 | BC16: 16/4/2026 | BD16: 17.25 | BE16: Efectivo | BI16: =(AX16+AZ16+BA16)-(BD16+BG16) -> 0 | BJ16: C02636 | BK16: 17.25 | BL16: 0 | BM16: 46151 | BT16: =(BI16+BK16+BL16)-(BO16+BR16) -> 17.25
A17: 020 | B17: VASQUEZ BUENO LUIS ALEJANDRO | C17: 172.16.1.7 | D17: ACTIVO | E17: M | G17: 0107835571 | H17: BAÑOS | I17: SI | J17: CALLE LLAVERO Y EL CALVARIO | K17: buenolastenia@gmail.com | L17: 0968397062 0992237922 | M17: 20baluisv | N17: 44438 | O17: 650M/650M | P17: GRATIS | Q17: 0 | R17: C02249 | S17: 23 | T17: 0 | U17: 46041 | V17: 46036 | W17: 23 | X17: Efectivo | AB17: =Q17+S17+T17-W17-Z17 -> 0 | AC17: C02357 | AD17: 23 | AE17: 0 | AF17: 46072 | AG17: 46064 | AH17: 23 | AI17: Efectivo | AM17: =(AB17+AD17+AE17)-(AH17+AK17) -> 0 | AN17: C02459 | AO17: 23 | AP17: 0 | AQ17: 46100 | AR17: 10/3/2026 | AS17: 23 | AT17: JEP | AX17: =(AM17+AO17+AP17)-(AS17+AV17) -> 0 | AY17: C02577 | AZ17: 23 | BA17: 0 | BB17: 46131 | BC17: 10/4/2026 | BD17: 23 | BE17: Efectivo | BI17: =(AX17+AZ17+BA17)-(BD17+BG17) -> 0 | BJ17: C02689 | BK17: 23 | BL17: 0 | BM17: 46161 | BT17: =(BI17+BK17+BL17)-(BO17+BR17) -> 23
A18: 021 | B18: GUAMAN YUNGA NARCISA PIEDAD | C18: 172.16.5.44 | D18: ACTIVO | E18: F | G18: 0106385578 | H18: BAÑOS | I18: SI | J18: SECTOR HUIZHIL | K18: facturas.labsll@gmail.com | L18: 0939645686 | M18: 21baguamann | N18: 45992 | O18: 600M/600M | P18: GRATIS | Q18: 0 | S18: 20.54 | T18: 0 | U18: 46041 | V18: 26/1/2026 | W18: 20.54 | X18: Efectivo | AB18: =Q18+S18+T18-W18-Z18 -> 0 | AC18: SIN FACTURA | AD18: 20.54 | AE18: 2 | AF18: 46072 | AG18: 46078.514 | AH18: 22.54 | AI18: Efectivo | AM18: =(AB18+AD18+AE18)-(AH18+AK18) -> 0 | AN18: SIN FACTURA | AO18: 20.54 | AP18: 2 | AQ18: 46100 | AR18: 25/3/2026 | AS18: 20.54 | AT18: Efectivo | AV18: 2 | AW18: Efectivo | AX18: =(AM18+AO18+AP18)-(AS18+AV18) -> 0 | AY18: SIN FACTURA | AZ18: 20.54 | BA18: 2 | BB18: 46131 | BC18: 46487 | BD18: 20.54 | BE18: Efectivo | BG18: 2 | BH18: Efectivo | BI18: =(AX18+AZ18+BA18)-(BD18+BG18) -> 0 | BK18: 20.54 | BL18: 2 | BM18: 46161 | BT18: =(BI18+BK18+BL18)-(BO18+BR18) -> 22.54
A19: 023 | B19: BALAREZO DURAN MARIA ELENA | C19: 172.16.1.9 | D19: ACTIVO | E19: F | G19: 0102434560 | H19: BAÑOS | I19: SI | J19: PASEO DE LA GUADALUPANA | K19: mariaelenab2011@hotmail.com | L19: 0959852484 0992424963 4097678 | N19: 44440 | O19: 100M/100M | P19: GRATIS | Q19: 0 | R19: C02189 | S19: 17.25 | T19: 0 | U19: 46041 | V19: 46045 | W19: 34.5 | X19: JEP | AB19: =Q19+S19+T19-W19-Z19 -> -17.25 | AC19: C02300 | AD19: 17.25 | AE19: 0 | AF19: 46072 | AG19: 46073 | AH19: 17.25 | AI19: JEP | AM19: =(AB19+AD19+AE19)-(AH19+AK19) -> -17.25 | AN19: C02410 | AO19: 17.25 | AP19: 0 | AQ19: 46100 | AX19: =(AM19+AO19+AP19)-(AS19+AV19) -> 0 | AY19: C02523 | AZ19: 17.25 | BA19: 0 | BB19: 46131 | BC19: 27/4/2026 | BD19: 20 | BE19: JEP | BI19: =(AX19+AZ19+BA19)-(BD19+BG19) -> -2.75 | BJ19: C02637 | BK19: 17.25 | BL19: 0 | BM19: 46161 | BT19: =(BI19+BK19+BL19)-(BO19+BR19) -> 14.5
A20: 024 | B20: SANCHEZ GUARANGO DIGNA ISABEL | C20: 172.16.4.14 | D20: ACTIVO | E20: F | G20: 0105975387 | H20: BAÑOS | I20: SI | J20: ALFONSO CARRION Y AV. RICARDO DURAN | K20: sanchezdigna284@gmail.com | L20: 0967656705 0990886597 | N20: 44446 | O20: 650M/650M | P20: GRATIS | Q20: 0 | R20: C02250 | S20: 23 | T20: 0 | U20: 46037 | V20: 26/1/2026 | W20: 23 | X20: Efectivo | AB20: =Q20+S20+T20-W20-Z20 -> 0 | AC20: C02358 | AD20: 23 | AE20: 0 | AF20: 46068 | AG20: 46076.807 | AH20: 23 | AI20: Efectivo | AM20: =(AB20+AD20+AE20)-(AH20+AK20) -> 0 | AN20: C02460 | AO20: 23 | AP20: 0 | AQ20: 46096 | AR20: 25/3/2026 | AS20: 23 | AT20: Efectivo | AX20: =(AM20+AO20+AP20)-(AS20+AV20) -> 0 | AY20: C02578 | AZ20: 23 | BA20: 0 | BB20: 46127 | BC20: 24/4/2026 | BD20: 23 | BE20: Efectivo | BI20: =(AX20+AZ20+BA20)-(BD20+BG20) -> 0 | BJ20: C02690 | BK20: 23 | BL20: 0 | BM20: 46157 | BT20: =(BI20+BK20+BL20)-(BO20+BR20) -> 23
A21: 025 | B21: SIGUA LOJANO OLGA CRISTINA | C21: 172.16.1.11 | D21: ACTIVO | E21: F | G21: 0105084875 | H21: BAÑOS | I21: NO | J21: VIA LAS MINAS BAÑOS | K21: olgasigua1985@gmail.com | L21: 0987141328 | N21: 44459 | O21: 100M/100M | P21: GRATIS | Q21: -0.75 | R21: C02190 | S21: 18 | T21: 0 | U21: 46032 | V21: 46143 | W21: 17.25 | X21: Efectivo | AB21: =Q21+S21+T21-W21-Z21 -> 0 | AC21: SIN FACTURA | AD21: 18 | AE21: 0 | AF21: 46063 | AG21: 46059.787 | AH21: 18 | AI21: Efectivo | AM21: =(AB21+AD21+AE21)-(AH21+AK21) -> 0 | AN21: SIN FACTURA | AO21: 18 | AP21: 0 | AQ21: 46091 | AR21: 46087.515 | AS21: 18 | AT21: Efectivo | AX21: =(AM21+AO21+AP21)-(AS21+AV21) -> 0 | AY21: SIN FACTURA | AZ21: 18 | BA21: 0 | BB21: 46122 | BC21: 46119.345 | BD21: 18 | BE21: Efectivo | BI21: =(AX21+AZ21+BA21)-(BD21+BG21) -> 0 | BK21: 18 | BL21: 0 | BM21: 46152 | BN21: 46148.345 | BO21: 18 | BP21: Efectivo | BT21: =(BI21+BK21+BL21)-(BO21+BR21) -> 0
A22: 029 | B22: BARBECHO ZHIÑIN MARIA BELEN | C22: 172.16.1.15 | D22: ACTIVO | E22: M | G22: 0150669596 | H22: BAÑOS | I22: NO | J22: CALLE EL CALVARIO | K22: mariabarbechocris@gmail.com | L22: 0997383316 0980921524 | N22: 45481 | O22: 100M/100M | P22: GRATIS | Q22: 0 | R22: C02191 | S22: 17.25 | T22: 0 | U22: 46036 | V22: 22/1/2026 | W22: 17.25 | X22: Efectivo | AB22: =Q22+S22+T22-W22-Z22 -> 0 | AC22: C02301 | AD22: 17.25 | AE22: 0 | AF22: 46067 | AG22: 46073.756 | AH22: 17.25 | AI22: Efectivo | AM22: =(AB22+AD22+AE22)-(AH22+AK22) -> 0 | AN22: C02411 | AO22: 17.25 | AP22: 0 | AQ22: 46095 | AR22: 46097.497 | AS22: 17.25 | AT22: Efectivo | AX22: =(AM22+AO22+AP22)-(AS22+AV22) -> 0 | AY22: C02524 | AZ22: 17.25 | BA22: 0 | BB22: 46126 | BC22: 16/4/2026 | BD22: 17.25 | BE22: Efectivo | BI22: =(AX22+AZ22+BA22)-(BD22+BG22) -> 0 | BJ22: C02638 | BK22: 17.25 | BL22: 0 | BM22: 46156 | BT22: =(BI22+BK22+BL22)-(BO22+BR22) -> 17.25
A23: 030 | B23: PINTADO GUAMAN MANUEL VICENTE | C23: 172.16.1.16 | D23: ACTIVO | E23: M | G23: 0102319902001 | H23: BAÑOS | I23: NO | J23: CALLE LA CALIZA Y RICARDO DURAN | K23: ecuadistribuidorvp@gmail.com | L23: 0997443605 | M23: 30bamanuelp | N23: 44488 | O23: 650M/650M | P23: GRATIS | Q23: 0 | R23: C02192 | S23: 17.25 | T23: 0 | U23: 46041 | V23: 46030 | W23: 17.25 | X23: JEP | AB23: =Q23+S23+T23-W23-Z23 -> 0 | AC23: C02302 | AD23: 17.25 | AE23: 0 | AF23: 46072 | AG23: 46072 | AH23: 17.25 | AI23: JEP | AM23: =(AB23+AD23+AE23)-(AH23+AK23) -> 0 | AN23: C02412 | AO23: 17.25 | AP23: 0 | AQ23: 46100 | AR23: 16/3/2026 | AS23: 17.25 | AT23: Pichincha | AX23: =(AM23+AO23+AP23)-(AS23+AV23) -> 0 | AY23: C02525 | AZ23: 17.25 | BA23: 0 | BB23: 46131 | BC23: 14/04/2026 | BD23: 17.25 | BE23: JEP | BI23: =(AX23+AZ23+BA23)-(BD23+BG23) -> 0 | BJ23: C02639 | BK23: 17.25 | BL23: 0 | BM23: 46161 | BT23: =(BI23+BK23+BL23)-(BO23+BR23) -> 17.25
A24: 031 | B24: PEÑALOZA BALAREZO DIANA MARCELA | C24: 172.16.2.15 | D24: ACTIVO | E24: F | G24: 0104386917 | H24: BAÑOS | I24: NO | J24: PASEO DE LA GUADALUPANA | K24: flakitaconK23@gmail.com | L24: 0979162869 | N24: 44488 | O24: 100M/100M | P24: GRATIS | Q24: 0 | S24: 17.25 | T24: 0 | U24: 46041 | V24: 46049 | W24: 17.25 | X24: JEP | AB24: =Q24+S24+T24-W24-Z24 -> 0 | AC24: C02303 | AD24: 17.25 | AE24: 0 | AF24: 46072 | AG24: 46076 | AH24: 17.25 | AI24: Efectivo | AM24: =(AB24+AD24+AE24)-(AH24+AK24) -> 0 | AN24: C02413 | AO24: 17.25 | AP24: 0 | AQ24: 46100 | AR24: 25/3/2026 | AS24: 17.25 | AT24: Pichincha | AX24: =(AM24+AO24+AP24)-(AS24+AV24) -> 0 | AY24: C02526 | AZ24: 17.25 | BA24: 0 | BB24: 46131 | BI24: =(AX24+AZ24+BA24)-(BD24+BG24) -> 17.25 | BJ24: C02640 | BK24: 17.25 | BL24: 0 | BM24: 46161 | BT24: =(BI24+BK24+BL24)-(BO24+BR24) -> 34.5
A25: 032 | B25: CARRILLO DOMINGUEZ JHOANA ELIZABETH | C25: 172.16.3.3 | D25: ACTIVO | F25: 12 | G25: 0105877864 | H25: YANUNCAY | I25: SI | J25: CONTROL SUR - SALTO DE LA SOGA Y DE LA PAJARA PINTA | K25: carrillo.jhoana@yahoo.com | L25: 0980444195 0995635986 | N25: 44489 | O25: 800M/800M | P25: GRATIS | Q25: 0 | R25: C02291 | S25: 32.2 | T25: 0 | U25: 46031 | V25: 46036 | W25: 32.2 | X25: JEP | AB25: =Q25+S25+T25-W25-Z25 -> 0 | AC25: C02395 | AD25: 32.2 | AE25: 0 | AF25: 46062 | AG25: 46073 | AH25: 35 | AI25: JEP | AM25: =(AB25+AD25+AE25)-(AH25+AK25) -> -2.8 | AN25: SIN FACTURA | AO25: 32.2 | AP25: 0 | AQ25: 46090 | AR25: 13/3/2026 | AS25: 32.2 | AT25: JEP | AX25: =(AM25+AO25+AP25)-(AS25+AV25) -> -2.8 | AY25: SIN FACTURA | AZ25: 32.2 | BA25: 0 | BB25: 46121 | BC25: 14/4/2026 | BD25: 32.2 | BE25: JEP | BI25: =(AX25+AZ25+BA25)-(BD25+BG25) -> -2.8 | BK25: 32.2 | BL25: 0 | BM25: 46151 | BT25: =(BI25+BK25+BL25)-(BO25+BR25) -> 29.4
A26: 033 | B26: TOBAY ALVAREZ MONICA ISABEL | C26: 172.16.0.2 | D26: EN PROCESO | E26: F | G26: 0106133002 | H26: BAÑOS | I26: SI | J26: NARANCAY ALTO - CUCHILOMA | K26: tobaymiki@gmail.com | L26: 0967964254 | N26: 44492 | O26: 100M/100M | P26: GRATIS | Q26: 164.5 | T26: 0 | U26: 46036 | AB26: =Q26+S26+T26-W26-Z26 -> 164.5 | AC26: SIN FACTURA | AE26: 0 | AF26: 46067 | AM26: =(AB26+AD26+AE26)-(AH26+AK26) -> 164.5 | AN26: SIN FACTURA | AP26: 0 | AQ26: 46095 | AX26: =(AM26+AO26+AP26)-(AS26+AV26) -> 164.5 | AY26: SIN FACTURA | BA26: 0 | BB26: 46126 | BI26: =(AX26+AZ26+BA26)-(BD26+BG26) -> 164.5 | BL26: 0 | BM26: 46156 | BT26: =(BI26+BK26+BL26)-(BO26+BR26) -> 164.5
A27: 035 | B27: MOROCHO QUITUIZACA MIRIAN PATRICIA | C27: 172.16.0.10 | D27: ACTIVO | E27: F | G27: 0107236390 | H27: BAÑOS | I27: NO | J27: VIA AL CHORRO CARROLOMA | K27: mirianmorocho017@gmail.com | L27: 0969892598 0969955271 | N27: 44501 | O27: 650M/650M | P27: GRATIS | Q27: 0 | R27: C02251 | S27: 23 | T27: 0 | U27: 46031 | V27: 46034 | W27: 23 | X27: Efectivo | AB27: =Q27+S27+T27-W27-Z27 -> 0 | AC27: C02359 | AD27: 23 | AE27: 0 | AF27: 46062 | AG27: 46064.76 | AH27: 23 | AI27: Efectivo | AM27: =(AB27+AD27+AE27)-(AH27+AK27) -> 0 | AN27: C02461 | AO27: 23 | AP27: 0 | AQ27: 46090 | AR27: 9/3/2026 | AS27: 23 | AT27: Pichincha | AX27: =(AM27+AO27+AP27)-(AS27+AV27) -> 0 | AY27: C02579 | AZ27: 23 | BA27: 0 | BB27: 46121 | BC27: 4/10/2026 | BD27: 23 | BE27: Efectivo | BI27: =(AX27+AZ27+BA27)-(BD27+BG27) -> 0 | BJ27: C02691 | BK27: 23 | BL27: 0 | BM27: 46151 | BT27: =(BI27+BK27+BL27)-(BO27+BR27) -> 23
A28: 036 | B28: SANCHEZ BURBANO ALICIA LUCIA | C28: 172.16.3.7 | D28: ACTIVO | E28: F | G28: 0602095416 | H28: YANUNCAY | I28: SI | J28: VIA NARANCAY | K28: pamelagranizo1992@gmail.com | L28: 0962855527 0984503895 | M28: 36baaliciab | N28: 44536 | O28: 650M/650M | P28: GRATIS | Q28: 0 | S28: 25 | T28: 0 | U28: 46041 | V28: 46036 | W28: 25 | X28: Pichincha | AB28: =Q28+S28+T28-W28-Z28 -> 0 | AC28: SIN FACTURA | AD28: 25 | AE28: 0 | AF28: 46072 | AG28: 46061 | AH28: 25 | AI28: JEP | AM28: =(AB28+AD28+AE28)-(AH28+AK28) -> 0 | AN28: SIN FACTURA | AO28: 25 | AP28: 0 | AQ28: 46100 | AR28: 11/3/2026 | AS28: 50 | AT28: Pichincha | AX28: =(AM28+AO28+AP28)-(AS28+AV28) -> -25 | AY28: SIN FACTURA | AZ28: 25 | BA28: 0 | BB28: 46131 | BI28: =(AX28+AZ28+BA28)-(BD28+BG28) -> 0 | BK28: 25 | BL28: 0 | BM28: 46161 | BT28: =(BI28+BK28+BL28)-(BO28+BR28) -> 25
A29: 037 | B29: SIGUA LOJANO FREDY BOLIVAR | C29: 172.16.1.18 | D29: ACTIVO | E29: M | G29: 0106101801 | H29: BAÑOS | I29: NO | J29: VIA LAS MINAS BAÑOS | K29: fredybolivar321@gmail.com | L29: 0987141328 0997253643 | N29: 44545 | O29: 100M/100M | P29: GRATIS | Q29: 0 | R29: C02193 | S29: 17.25 | T29: 0 | U29: 46031 | V29: 46025 | W29: 17.5 | X29: Pichincha | AB29: =Q29+S29+T29-W29-Z29 -> -0.25 | AC29: C02304 | AD29: 17.25 | AE29: 0 | AF29: 46062 | AG29: 46055.808 | AH29: 17.25 | AI29: Efectivo | AM29: =(AB29+AD29+AE29)-(AH29+AK29) -> -0.25 | AN29: C02414 | AO29: 17.25 | AP29: 0 | AQ29: 46090 | AR29: 1/3/2026 | AS29: 17.25 | AT29: Pichincha | AX29: =(AM29+AO29+AP29)-(AS29+AV29) -> -0.25 | AY29: C02527 | AZ29: 17.25 | BA29: 0 | BB29: 46121 | BC29: 1/4/2026 | BD29: 17.5 | BE29: Pichincha | BI29: =(AX29+AZ29+BA29)-(BD29+BG29) -> -0.5 | BJ29: C02641 | BK29: 17.25 | BL29: 0 | BM29: 46151 | BN29: 3/5/2026 | BO29: 17.5 | BP29: Pichincha | BT29: =(BI29+BK29+BL29)-(BO29+BR29) -> -0.75
A30: 038 | B30: SIGUA LOJANO NORMA PATRICIA | C30: 172.16.1.19 | D30: ACTIVO | E30: F | G30: 0104130505 | H30: BAÑOS | I30: NO | J30: VIA LAS MINAS BAÑOS | K30: nathalyv728@gmail.com | L30: 0959530127 0990345417 | N30: 44545 | O30: 100M/100M | P30: GRATIS | Q30: 0 | R30: C02194 | S30: 17.25 | T30: 0 | U30: 46031 | V30: 46024 | W30: 17.25 | X30: JEP | AB30: =Q30+S30+T30-W30-Z30 -> 0 | AC30: C02305 | AD30: 17.25 | AE30: 0 | AF30: 46062 | AG30: 46057 | AH30: 17.25 | AI30: JEP | AM30: =(AB30+AD30+AE30)-(AH30+AK30) -> 0 | AN30: C02415 | AO30: 17.25 | AP30: 0 | AQ30: 46090 | AR30: 6/3/2026 | AS30: 17.25 | AT30: Efectivo | AX30: =(AM30+AO30+AP30)-(AS30+AV30) -> 0 | AY30: C02528 | AZ30: 17.25 | BA30: 0 | BB30: 46121 | BC30: 4/4/2026 | BD30: 17.25 | BE30: JEP | BI30: =(AX30+AZ30+BA30)-(BD30+BG30) -> 0 | BJ30: C02642 | BK30: 17.25 | BL30: 0 | BM30: 46151 | BT30: =(BI30+BK30+BL30)-(BO30+BR30) -> 17.25
A31: 039 | B31: SIGUA CRIOLLO CARMEN DE JESUS | C31: 172.16.1.20 | D31: ACTIVO | E31: F | G31: 0103456018 | H31: BAÑOS | I31: NO | J31: VIA LAS MINAS BAÑOS | K31: carmensigua75@gmail.com | L31: 0983571157 4092792 2893644 | N31: 46017 | O31: 800M/800M | P31: GRATIS | Q31: 0 | R31: C02292 | S31: =32.2+35 -> 67.2 | T31: 0 | U31: 46041 | V31: 26/1/2026 | W31: 67.2 | X31: Efectivo | AB31: =Q31+S31+T31-W31-Z31 -> 0 | AC31: SIN FACTURA | AD31: =32.2+35 -> 67.2 | AE31: 0 | AF31: 46072 | AG31: 46076 | AH31: 50 | AI31: Efectivo | AM31: =(AB31+AD31+AE31)-(AH31+AK31) -> 17.2 | AN31: C02504 | AO31: 32.2 | AP31: 0 | AQ31: 46100 | AR31: 46108.353 | AS31: 35 | AT31: Efectivo | AX31: =(AM31+AO31+AP31)-(AS31+AV31) -> 14.4 | AY31: SIN FACTURA | AZ31: 32.2 | BA31: 0 | BB31: 46131 | BC31: 24/4/2026 | BD31: 40 | BE31: Efectivo | BI31: =(AX31+AZ31+BA31)-(BD31+BG31) -> 6.6 | BK31: 32.2 | BL31: 0 | BM31: 46161 | BT31: =(BI31+BK31+BL31)-(BO31+BR31) -> 38.8
A32: 040 | B32: ZHAGUI DUGLLAY DIANA CECILIA | C32: 172.16.1.21 | D32: EN PROCESO | E32: F | G32: 0104928411 | H32: BAÑOS | I32: NO | J32: EL CALVARIO | K32: fabriciodugllay51@gmail.com | L32: 0992467080 099764171 0986234426 | N32: 44550 | O32: 650M/650M | P32: GRATIS | Q32: 83 | T32: 0 | U32: 46041 | AB32: =Q32+S32+T32-W32-Z32 -> 83 | AC32: SIN FACTURA | AE32: 0 | AF32: 46072 | AM32: =(AB32+AD32+AE32)-(AH32+AK32) -> 83 | AN32: SIN FACTURA | AP32: 0 | AQ32: 46100 | AX32: =(AM32+AO32+AP32)-(AS32+AV32) -> 83 | AY32: SIN FACTURA | BA32: 0 | BB32: 46131 | BI32: =(AX32+AZ32+BA32)-(BD32+BG32) -> 83 | BL32: 0 | BM32: 46161 | BT32: =(BI32+BK32+BL32)-(BO32+BR32) -> 83
A33: 043 | B33: MACAS GUALAN AIDA BEATRIZ | C33: 172.16.5.39 | D33: ACTIVO | E33: F | G33: 0107189680 | H33: BAÑOS | I33: SI | J33: SECTOR EL CHORRO CALLE GUADALUPANA | K33: macasaida7@gmail.com | L33: 0986292604 0989455393 | N33: 45859 | O33: 650M/650M | P33: 5 | Q33: 0 | S33: =20.54+10 -> 30.54 | T33: 0 | U33: 46036 | V33: 46049 | W33: 20.54 | X33: Efectivo | AB33: =Q33+S33+T33-W33-Z33 -> 10 | AC33: SIN FACTURA | AD33: 20.54 | AE33: 0 | AF33: 46067 | AG33: 46077 | AH33: 30.54 | AI33: Efectivo | AM33: =(AB33+AD33+AE33)-(AH33+AK33) -> 0 | AN33: SIN FACTURA | AO33: 20.54 | AP33: 0 | AQ33: 46095 | AR33: 46112.583 | AS33: 20.54 | AT33: Efectivo | AX33: =(AM33+AO33+AP33)-(AS33+AV33) -> 0 | AY33: SIN FACTURA | AZ33: 20.54 | BA33: 0 | BB33: 46126 | BI33: =(AX33+AZ33+BA33)-(BD33+BG33) -> 20.54 | BK33: 20.54 | BL33: 0 | BM33: 46156 | BT33: =(BI33+BK33+BL33)-(BO33+BR33) -> 41.08
A34: 045 | B34: SIGUA CRIOLLO CARMEN DE JESUS (PAPAS) | C34: 172.16.1.23 | D34: INACTIVO | E34: F | G34: 0103456018 | H34: BAÑOS | I34: NO | J34: VIA LAS MINAS BAÑOS | K34: carmensigua75@gmail.com | L34: 0983571157 4092792 0997217517 | N34: 44606 | O34: 100M/100M | P34: GRATIS | Q34: 0 | T34: 0 | AB34: =Q34+S34+T34-W34-Z34 -> 0 | AC34: SIN FACTURA | AE34: 0 | AM34: =(AB34+AD34+AE34)-(AH34+AK34) -> 0 | AN34: SIN FACTURA | AP34: 0 | AX34: =(AM34+AO34+AP34)-(AS34+AV34) -> 0 | AY34: SIN FACTURA | BA34: 0 | BI34: =(AX34+AZ34+BA34)-(BD34+BG34) -> 0 | BL34: 0 | BT34: =(BI34+BK34+BL34)-(BO34+BR34) -> 0
A35: 046 | B35: DUCHI GUAMAN ROSA NARCISA | C35: 172.16.1.24 | D35: ACTIVO | E35: F | G35: 0103831491 | H35: BAÑOS | I35: SI | J35: PASEO GUADALUPANA | K35: rosanarcisaduchiguaman@gmail.com | L35: 0997365597 2892124 | M35: 046roduchi | N35: 44701 | O35: 100M/100M | P35: 5 | Q35: 0 | R35: C02195 | S35: 17.25 | T35: 0 | U35: 46041 | V35: 46037 | W35: 17.25 | X35: Efectivo | AB35: =Q35+S35+T35-W35-Z35 -> 0 | AC35: C02306 | AD35: 17.25 | AE35: 0 | AF35: 46072 | AG35: 46071 | AH35: 17.25 | AI35: Efectivo | AM35: =(AB35+AD35+AE35)-(AH35+AK35) -> 0 | AN35: C02416 | AO35: 17.25 | AP35: 0 | AQ35: 46100 | AR35: 46100.63 | AS35: 17.25 | AT35: Efectivo | AX35: =(AM35+AO35+AP35)-(AS35+AV35) -> 0 | AY35: C02529 | AZ35: 17.25 | BA35: 0 | BB35: 46131 | BC35: 8/4/2026 | BD35: 17.25 | BE35: Efectivo | BI35: =(AX35+AZ35+BA35)-(BD35+BG35) -> 0 | BJ35: C02643 | BK35: 17.25 | BL35: 0 | BM35: 46161 | BT35: =(BI35+BK35+BL35)-(BO35+BR35) -> 17.25
A36: 047 | B36: PINCAY VALAREZO PAOLA MARIA | C36: 172.16.0.15 | D36: EN PROCESO | E36: F | G36: 0925492670 | H36: YANUNCAY | I36: SI | J36: CDLA. SANTA MARIA DE BAÑOS | K36: pandora_17@hotmail.com | L36: 0999214389 | N36: 44638 | O36: 100M/100M | Q36: 77.25 | T36: 0 | U36: 46041 | AB36: =Q36+S36+T36-W36-Z36 -> 77.25 | AC36: SIN FACTURA | AE36: 0 | AF36: 46072 | AM36: =(AB36+AD36+AE36)-(AH36+AK36) -> 77.25 | AN36: SIN FACTURA | AP36: 0 | AQ36: 46100 | AX36: =(AM36+AO36+AP36)-(AS36+AV36) -> 77.25 | AY36: SIN FACTURA | BA36: 0 | BB36: 46131 | BI36: =(AX36+AZ36+BA36)-(BD36+BG36) -> 77.25 | BL36: 0 | BM36: 46161 | BT36: =(BI36+BK36+BL36)-(BO36+BR36) -> 77.25
A37: 048 | B37: CAJAMARCA AYABACA MANUEL FABIAN | C37: 172.16.12.5 | D37: ACTIVO | E37: M | G37: 0104934302 | H37: YANUNCAY | I37: NO | J37: CALLE LA MACATECA | K37: cajamarcafabian857@gmail.com | L37: 0980484671 | N37: 44638 | O37: 650M/650M | Q37: 0 | R37: C02253 | S37: 23 | T37: 0 | U37: 46031 | V37: 46045.354 | W37: 23 | X37: Efectivo | AB37: =Q37+S37+T37-W37-Z37 -> 0 | AC37: C02360 | AD37: 23 | AE37: 0 | AF37: 46062 | AG37: 46064.534 | AH37: 23 | AI37: Efectivo | AM37: =(AB37+AD37+AE37)-(AH37+AK37) -> 0 | AN37: C02462 | AO37: 23 | AP37: 0 | AQ37: 46090 | AR37: 27/3/2026 | AS37: 23 | AT37: Efectivo | AX37: =(AM37+AO37+AP37)-(AS37+AV37) -> 0 | AY37: C02581 | AZ37: 23 | BA37: 0 | BB37: 46121 | BC37: 46134.472 | BD37: 23 | BE37: Efectivo | BI37: =(AX37+AZ37+BA37)-(BD37+BG37) -> 0 | BJ37: C02692 | BK37: 23 | BL37: 0 | BM37: 46151 | BT37: =(BI37+BK37+BL37)-(BO37+BR37) -> 23
A38: 049 | B38: BENENAULA CRIOLLO DARIO JAVIER | C38: 172.16.0.17 | D38: ACTIVO | E38: M | G38: 0105541270 | H38: YANUNCAY | I38: NO | J38: VIRGEN DE FATIMA ADBOCACION | K38: dariobene619@gmail.com | L38: 0968997963 0988356536 | M38: 49badariob | N38: 44641 | O38: 650M/650M | Q38: 0 | R38: C02254 | S38: 23 | T38: 0 | U38: 46047 | V38: 46048.818 | W38: 23 | X38: JEP | AB38: =Q38+S38+T38-W38-Z38 -> 0 | AC38: C02361 | AD38: 23 | AE38: 0 | AF38: 46078 | AG38: 46079 | AH38: 23 | AI38: JEP | AM38: =(AB38+AD38+AE38)-(AH38+AK38) -> 0 | AN38: C02463 | AO38: 23 | AP38: 0 | AQ38: 46106 | AR38: 26/3/2026 | AS38: 23 | AT38: JEP | AX38: =(AM38+AO38+AP38)-(AS38+AV38) -> 0 | AY38: C02580 | AZ38: 23 | BA38: 0 | BB38: 46137 | BC38: 27/04/2026 | BD38: 23 | BE38: Pichincha | BI38: =(AX38+AZ38+BA38)-(BD38+BG38) -> 0 | BJ38: C02693 | BK38: 23 | BL38: 0 | BM38: 46167 | BT38: =(BI38+BK38+BL38)-(BO38+BR38) -> 23
A39: 050 | B39: ACOSTA MERA JOSE RAMON | C39: 172.16.0.18 | D39: ACTIVO | E39: M | G39: 1309249397 | H39: YANUNCAY | I39: NO | J39: NARANCAY ALTO | K39: maritzashuir@gmail.com | L39: 0991567816 0988357336 | N39: 44642 | O39: 650M/650M | Q39: 0 | S39: 23 | T39: 0 | U39: 46041 | V39: 46050 | W39: 23 | X39: Pichincha | AB39: =Q39+S39+T39-W39-Z39 -> 0 | AC39: SIN FACTURA | AD39: 23 | AE39: 0 | AF39: 46072 | AG39: 46081 | AH39: 23 | AI39: Pichincha | AM39: =(AB39+AD39+AE39)-(AH39+AK39) -> 0 | AN39: SIN FACTURA | AO39: 23 | AP39: 0 | AQ39: 46100 | AR39: 46107.662 | AS39: 23 | AT39: Pichincha | AX39: =(AM39+AO39+AP39)-(AS39+AV39) -> 0 | AY39: SIN FACTURA | AZ39: 23 | BA39: 0 | BB39: 46131 | BC39: 29/04/2026 | BD39: 23 | BE39: Pichincha | BI39: =(AX39+AZ39+BA39)-(BD39+BG39) -> 0 | BK39: 23 | BL39: 0 | BM39: 46161 | BT39: =(BI39+BK39+BL39)-(BO39+BR39) -> 23
A40: 051 | B40: SAQUICELA GUAMAN MARIA DE LOURDES | C40: 172.16.11.3 | D40: ACTIVO | E40: F | G40: 0704053305 | H40: YANUNCAY | I40: NO | J40: MACATETA (ESQUINA) BARRIO SANTA MARIA | K40: facturas.labsll@gmail.com | L40: 0981579770 | M40: 051bamariag | N40: 44649 | O40: 650M/650M | Q40: 0 | R40: C02255 | S40: 23 | T40: 0 | U40: 46036 | V40: 46045 | W40: 23 | X40: JEP | AB40: =Q40+S40+T40-W40-Z40 -> 0 | AC40: C02362 | AD40: 23 | AE40: 0 | AF40: 46067 | AG40: 46076 | AH40: 23 | AI40: JEP | AM40: =(AB40+AD40+AE40)-(AH40+AK40) -> 0 | AN40: C02464 | AO40: 23 | AP40: 0 | AQ40: 46095 | AR40: 25/3/2026 | AS40: 23 | AT40: JEP | AX40: =(AM40+AO40+AP40)-(AS40+AV40) -> 0 | AY40: C02582 | AZ40: 23 | BA40: 0 | BB40: 46126 | BC40: 23/4/2026 | BD40: 23 | BE40: JEP | BI40: =(AX40+AZ40+BA40)-(BD40+BG40) -> 0 | BJ40: C02694 | BK40: 23 | BL40: 0 | BM40: 46156 | BT40: =(BI40+BK40+BL40)-(BO40+BR40) -> 23
...

Sheet SAYAUSI
B1: NAME | C1: IP | D1: ESTADO | E1: CED | F1: TIEMPO | G1: DOCUMENTS | H1: PARISH | I1: RENT | J1: DIRECTION | K1: MAIL | L1: CEL | M1: CUENTA | N1: INSTALATION DATE | O1: PLAN | P1: INS_PAYMENT | Q1: SALDO | R1: FACT DE DIC | S1: DECEMBER | T1: APP | U1: PAYMENT DATE | V1: CLIENT PAYMENT DATE | W1: INTERNET PAYMENT | X1: BANK | Y1: COD | Z1: TV | AA1: BANK | AB1: SALDO | AC1: FACT JANUARY | AD1: INTERNET PAYMENT | AE1: APP | AF1: PAYMENT DATE | AG1: CLIENT PAYMENT DATE | AH1: INTERNET PAYMENT | AI1: BANK | AJ1: COD | AK1: PLUS | AL1: BANK_PLUS | AM1: SALDO | AN1: FACTURAS | AO1: INTERNET PAYMENT | AP1: APP | AQ1: PAYMENT DATE | AR1: CLIENT PAYMENT DATE | AS1: INTERNET PAYMENT | AT1: BANK | AU1: COD | AV1: PLUS | AW1: BANK_PLUS | AX1: SALDO | AY1: FACTURAS | AZ1: INTERNET PAYMENT | BA1: APP | BB1: PAYMENT DATE | BC1: CLIENT PAYMENT DATE | BD1: INTERNET PAYMENT | BE1: BANK | BF1: COD | BG1: PLUS | BH1: BANK_PLUS | BI1: SALDO | BJ1: FACTURAS | BK1: INTERNET PAYMENT | BL1: APP | BM1: PAYMENT DATE | BN1: CLIENT PAYMENT DATE | BO1: INTERNET PAYMENT | BP1: BANK | BQ1: COD | BR1: PLUS | BS1: BANK_PLUS | BT1: SALDO | BU1: FACTURAS
A2: 001 | B2: YANEZ OCHOA MICHAEL LEONARDO | C2: 172.18.4.5 | D2: ACTIVO | E2: NO | F2: 24 | G2: 0105542450 | H2: SAYAUSI | I2: SI | J2: ORDOÑEZ LASSO SECTOR SANTA MARIA | K2: yaneztarquino91@gmail.com | L2: 0959229482 0980598322 0980650419 +593 98 079 8919 | N2: 46051 | O2: 600M/600M | P2: 16.8 | Q2: 0 | S2: 17.25 | U2: 46032 | V2: 46038 | W2: 17.25 | X2: Pichincha | Y2: 120476 | AB2: =S2+T2-W2-Z2 -> 0 | AC2: SIN FACTURA | AD2: 20.54 | AF2: 46063 | AG2: 46067 | AH2: 20.54 | AI2: Pichincha | AJ2: 128542 | AM2: =(AB2+AD2+AE2)-(AH2+AK2) -> 0 | AN2: SIN FACTURA | AO2: 20.54 | AQ2: 46091 | AR2: 24/3/2026 | AS2: 20.54 | AT2: Pichincha | AU2: 138498 | AX2: =(AM2+AO2+AP2)-(AS2+AV2) -> 0 | AY2: SIN FACTURA | AZ2: 20.54 | BB2: 46122 | BC2: 19/4/2026 | BD2: 20.54 | BE2: Pichincha | BF2: 142032 | BI2: =(AX2+AZ2+BA2)-(BD2+BG2) -> 0 | BK2: 20.54 | BM2: 46152 | BT2: =(BI2+BK2+BL2)-(BO2+BR2) -> 20.54
A3: 002 | B3: PACHECO PRADO FELIX JOSE | C3: 172.18.2.9 | D3: ACTIVO | E3: M | G3: 0104107701 | H3: SAYAUSI | I3: NO | J3: ORDOÑEZ LASSO FRENTE GASOLINERA PRIMAX | K3: facturas.labsll@gmail.com | L3: 0986600649 0999790946 | M3: 02sayafelixp | N3: 44481 | O3: 650M/650M | P3: GRATIS | Q3: 2.75 | S3: 17.25 | U3: 46041 | V3: 46045 | W3: 20 | X3: Pichincha | AB3: =Q3+S3+T3-W3-Z3 -> 0 | AC3: SIN FACTURA | AD3: 17.25 | AF3: 46072 | AG3: 46080 | AH3: 20 | AI3: Pichincha | AM3: =(AB3+AD3+AE3)-(AH3+AK3) -> -2.75 | AN3: SIN FACTURA | AO3: 17.25 | AQ3: 46100 | AR3: 30/3/2026 | AS3: 20 | AT3: Pichincha | AX3: =(AM3+AO3+AP3)-(AS3+AV3) -> -5.5 | AY3: SIN FACTURA | AZ3: 17.25 | BB3: 46131 | BI3: =(AX3+AZ3+BA3)-(BD3+BG3) -> 11.75 | BK3: 17.25 | BM3: 46161 | BT3: =(BI3+BK3+BL3)-(BO3+BR3) -> 29
A4: 006 | B4: GUTAMA EHUÑIR DIGNA NOEMI | C4: 172.18.2.4 | D4: INACTIVO | G4: 0107345217 | H4: SAYAUSI | I4: SI | J4: ORDOÑEZ LASSO Y HIERBA LUISA | K4: dignagutama9@hotmail.com | L4: 0986096326 | N4: 45184 | O4: 100M/100M | P4: GRATIS | Q4: 0 | AB4: =S4+T4-W4-Z4 -> 0 | AC4: SIN FACTURA | AM4: =(AB4+AD4+AE4)-(AH4+AK4) -> 0 | AN4: SIN FACTURA | AX4: =(AM4+AO4+AP4)-(AS4+AV4) -> 0 | AY4: SIN FACTURA | BI4: =(AX4+AZ4+BA4)-(BD4+BG4) -> 0 | BT4: =(BI4+BK4+BL4)-(BO4+BR4) -> 0
A5: 007 | B5: FONSECA SILVA MARCOS ENRIQUE | C5: 172.18.2.55 | D5: ACTIVO | E5: M | G5: 0152598603 | H5: SAYAUSI | I5: SI | J5: VIA DEL TEJAR | K5: fonsecam199.5@gmail.com | L5: 0963154411 0978797350 | N5: 44508 | O5: 650M/650M | P5: GRATIS | Q5: 0 | S5: 23 | U5: 46041 | V5: 46043 | W5: 23 | X5: Pichincha | AB5: =S5+T5-W5-Z5 -> 0 | AC5: C0360 | AD5: 23 | AF5: 46072 | AG5: 46072 | AH5: 23 | AI5: Pichincha | AJ5: 129768 | AM5: =(AB5+AD5+AE5)-(AH5+AK5) -> 0 | AN5: C0408 | AO5: 23 | AQ5: 46100 | AR5: 24/3/2026 | AS5: 23 | AT5: Pichincha | AU5: 138500 | AX5: =(AM5+AO5+AP5)-(AS5+AV5) -> 0 | AY5: C0453 | AZ5: 23 | BB5: 46131 | BC5: 20/4/2026 | BD5: 23 | BE5: Pichincha | BI5: =(AX5+AZ5+BA5)-(BD5+BG5) -> 0 | BJ5: C0497 | BK5: 23 | BM5: 46161 | BT5: =(BI5+BK5+BL5)-(BO5+BR5) -> 23
A6: 009 | B6: PACHO VILLA NORMA MAGDALENA | C6: 172.18.2.6 | D6: CORTESIA | E6: F | G6: 0105168165 | H6: SAYAUSI | I6: SI | J6: ORDOÑEZ LASSO FRENTE A LA BOMBA PRIMAX | K6: villanorma755@gmail.com | L6: 0986963187 0980269740 | M6: 52sayanormap | N6: 44508 | O6: 650M/650M | P6: GRATIS | Q6: 0 | S6: 0 | U6: 46038 | AB6: =S6+T6-W6-Z6 -> 0 | AC6: SIN FACTURA | AD6: 0 | AF6: 46069 | AM6: =(AB6+AD6+AE6)-(AH6+AK6) -> 0 | AN6: SIN FACTURA | AO6: 0 | AQ6: 46097 | AX6: =(AM6+AO6+AP6)-(AS6+AV6) -> 0 | AY6: SIN FACTURA | AZ6: 0 | BB6: 46128 | BI6: =(AX6+AZ6+BA6)-(BD6+BG6) -> 0 | BK6: 0 | BM6: 46158 | BT6: =(BI6+BK6+BL6)-(BO6+BR6) -> 0
A7: 010 | B7: VELECELA GUNCAY MARTHA LUCIA | C7: 172.18.1.3 | D7: ACTIVO | E7: F | G7: 0104301726 | H7: SAYAUSI | I7: NO | J7: LA HERMITA SAYAUSI | K7: mvelecela.1981@gmail.com | L7: 0997365619 0997439598 | N7: 44513 | O7: 650M/650M | P7: GRATIS | Q7: 0 | S7: 23 | U7: 46041 | V7: 46049 | W7: 23 | X7: JEP | AB7: =S7+T7-W7-Z7 -> 0 | AC7: C0361 | AD7: 23 | AF7: 46072 | AG7: 46076 | AH7: 23 | AI7: JEP | AM7: =(AB7+AD7+AE7)-(AH7+AK7) -> 0 | AN7: C0409 | AO7: 23 | AQ7: 46100 | AR7: 25/3/2026 | AS7: 23 | AT7: JEP | AX7: =(AM7+AO7+AP7)-(AS7+AV7) -> 0 | AY7: C0454 | AZ7: 23 | BB7: 46131 | BC7: 28/04/2026 | BD7: 23 | BE7: JEP | BI7: =(AX7+AZ7+BA7)-(BD7+BG7) -> 0 | BJ7: C0498 | BK7: 23 | BM7: 46161 | BT7: =(BI7+BK7+BL7)-(BO7+BR7) -> 23
A8: 011 | B8: GOMEZ SANGURIMA MARCO OSWALDO | C8: 172.18.1.4 | D8: ACTIVO | E8: M | G8: 0106626161 | H8: SAYAUSI | I8: NO | J8: SAN MIGUEL - LA HERMITA | K8: marco-gomez04@hotmail.com | L8: 0983509196 0992504946 074189279 | N8: 46091 | O8: 100M/100M | P8: GRATIS | Q8: 0 | S8: 17.25 | U8: 46036 | V8: 21/1/2026 | W8: 17.25 | X8: Pichincha | AB8: =S8+T8-W8-Z8 -> 0 | AC8: SIN FACTURA | AD8: 17.25 | AF8: 46067 | AG8: 46058 | AH8: 17.25 | AI8: Pichincha | AM8: =(AB8+AD8+AE8)-(AH8+AK8) -> 0 | AN8: SIN FACTURA | AO8: 17.25 | AQ8: 46095 | AR8: 4/3/2026 | AS8: 17.25 | AT8: JEP | AX8: =(AM8+AO8+AP8)-(AS8+AV8) -> 0 | AY8: SIN FACTURA | AZ8: 17.25 | BB8: 46126 | BC8: 6/4/2026 | BD8: 17.25 | BE8: Pichincha | BI8: =(AX8+AZ8+BA8)-(BD8+BG8) -> 0 | BK8: 17.25 | BM8: 46156 | BT8: =(BI8+BK8+BL8)-(BO8+BR8) -> 17.25
A9: 012 | B9: CAJAMARCA FAJARDO CLAUDIO RIGOBERTO | C9: 172.18.2.10 | D9: ACTIVO | E9: M | G9: 0104009352 | H9: SAYAUSI | I9: NO | J9: AV. TEJAR Y CAMINO SAN MIGUEL DE PUTUSHI | K9: claudio78cajamarca@gmail.com | L9: 0979416436 0991275404 | M9: 12sayasoniaa | N9: 45783 | O9: 100M/100M | P9: GRATIS | Q9: 0 | S9: 17.25 | T9: 4 | U9: 46041 | V9: 46045 | W9: 17.25 | X9: Pichincha | Z9: 4 | AA9: Pichincha | AB9: =S9+T9-W9-Z9 -> 0 | AC9: SIN FACTURA | AD9: 17.25 | AE9: 4 | AF9: 46072 | AG9: 46076 | AH9: 17.25 | AI9: JEP | AK9: 4 | AL9: JEP | AM9: =(AB9+AD9+AE9)-(AH9+AK9) -> 0 | AN9: SIN FACTURA | AO9: 17.25 | AP9: 4 | AQ9: 46100 | AR9: 26/26/2026 | AS9: 17.25 | AT9: Pichincha | AV9: 4 | AW9: Pichincha | AX9: =(AM9+AO9+AP9)-(AS9+AV9) -> 0 | AY9: SIN FACTURA | AZ9: 17.25 | BA9: 4 | BB9: 46131 | BC9: 1/4/2026 | BD9: 17.25 | BE9: JEP | BG9: 4 | BH9: JEP | BI9: =(AX9+AZ9+BA9)-(BD9+BG9) -> 0 | BK9: 17.25 | BL9: 4 | BM9: 46161 | BT9: =(BI9+BK9+BL9)-(BO9+BR9) -> 21.25
A10: 013 | B10: MORALES TENEGAÑAY JESSICA LUCIA | C10: 172.18.1.34 | D10: INACTIVO | E10: F | G10: 0105659502 | H10: SAYAUSI | I10: SI | J10: SUBIDA A SAN MIGUEL SECTOR IGLESIA NUEVA | K10: rosiparedes714@gmail.com | L10: 0992964104 | N10: 44592 | O10: 100M/100M | P10: GRATIS | Q10: 37.25 | AB10: =S10+T10-W10-Z10 -> 0 | AC10: SIN FACTURA | AM10: =(AB10+AD10+AE10)-(AH10+AK10) -> 0 | AN10: SIN FACTURA | AX10: =(AM10+AO10+AP10)-(AS10+AV10) -> 0 | AY10: SIN FACTURA | BI10: =(AX10+AZ10+BA10)-(BD10+BG10) -> 0 | BT10: =(BI10+BK10+BL10)-(BO10+BR10) -> 0
A11: 017 | B11: LEON VILLA SEGUNDO RODOLFO | C11: 10.67.2.254 | D11: INACTIVO | E11: M | G11: 0103229399 | H11: SAYAUSI | I11: NO | J11: SAN MIGUEL SECTOR TEMPLO CHINO | K11: facturas.labsll@gmail.com | L11: 0993568122 0995674041 | N11: 44516 | O11: 650M/650M | P11: GRATIS | Q11: 0 | AB11: =S11+T11-W11-Z11 -> 0 | AC11: SIN FACTURA | AM11: =(AB11+AD11+AE11)-(AH11+AK11) -> 0 | AN11: SIN FACTURA | AX11: =(AM11+AO11+AP11)-(AS11+AV11) -> 0 | AY11: SIN FACTURA | BI11: =(AX11+AZ11+BA11)-(BD11+BG11) -> 0 | BT11: =(BI11+BK11+BL11)-(BO11+BR11) -> 0
A12: 018 | B12: CEDILLO PALTA ANGEL AMBROCIO | C12: 172.18.2.15 | D12: INACTIVO | G12: 0102600814 | H12: SAYAUSI | I12: NO | J12: ORDOÑEZ LASO Y ROSAL | K12: angelambrosiocedillo@hotmail.com | L12: 0992304985 4193019 | N12: 44510 | O12: 650M/650M | P12: GRATIS | Q12: 0 | AB12: =S12+T12-W12-Z12 -> 0 | AC12: SIN FACTURA | AM12: =(AB12+AD12+AE12)-(AH12+AK12) -> 0 | AN12: SIN FACTURA | AX12: =(AM12+AO12+AP12)-(AS12+AV12) -> 0 | AY12: SIN FACTURA | BI12: =(AX12+AZ12+BA12)-(BD12+BG12) -> 0 | BT12: =(BI12+BK12+BL12)-(BO12+BR12) -> 0
A13: 020 | B13: ROSERO CAJAMARCA EDUARDO MARCIAL | C13: 172.18.2.17 | D13: ACTIVO | E13: M | F13: 12 | G13: 2100399233 | H13: SAYAUSI | I13: SI | J13: ORDOÑEZ LASO Y HIERBA LUISA | K13: eduardorosero2012@hotmail.com | L13: 0962191932 | N13: 44888 | O13: 100M/100M | P13: 5 | Q13: 0 | S13: 17.25 | U13: 46031 | V13: 21/1/2026 | W13: 17.25 | X13: Pichincha | AB13: =S13+T13-W13-Z13 -> 0 | AC13: SIN FACTURA | AD13: 17.25 | AF13: 46062 | AG13: 46072 | AH13: 17.25 | AI13: Pichincha | AJ13: 129770 | AM13: =(AB13+AD13+AE13)-(AH13+AK13) -> 0 | AN13: SIN FACTURA | AO13: 17.25 | AQ13: 46090 | AR13: 30/3/2026 | AS13: 17.25 | AT13: Pichincha | AX13: =(AM13+AO13+AP13)-(AS13+AV13) -> 0 | AY13: SIN FACTURA | AZ13: 17.25 | BB13: 46121 | BC13: 11/4/2026 | BD13: 17.25 | BE13: Pichincha | BF13: 141504 | BI13: =(AX13+AZ13+BA13)-(BD13+BG13) -> 0 | BK13: 17.25 | BM13: 46151 | BT13: =(BI13+BK13+BL13)-(BO13+BR13) -> 17.25
A14: 021 | B14: PACHECO PANGOL JENNY MARISOL | C14: 172.18.1.5 | D14: ACTIVO | E14: F | F14: 24 | G14: 0104551742 | H14: SAYAUSI | I14: NO | J14: SAN MIGUEL SECTOR HERMITA | K14: marcocalu1710@gmail.com | L14: 0980870614 0997132402 | N14: 45567 | O14: 650M/650M | P14: GRATIS | Q14: 0.4 | S14: 23 | U14: 46041 | V14: 46043 | W14: 23 | X14: JEP | AB14: =S14+T14-W14-Z14 -> 0 | AC14: C0362 | AD14: 23 | AF14: 46072 | AG14: 46072 | AH14: 23 | AI14: JEP | AM14: =(AB14+AD14+AE14)-(AH14+AK14) -> 0 | AN14: C0410 | AO14: 23 | AQ14: 46100 | AR14: 25/3/2026 | AS14: 23 | AT14: JEP | AX14: =(AM14+AO14+AP14)-(AS14+AV14) -> 0 | AY14: C0455 | AZ14: 23 | BB14: 46131 | BC14: 28/4/2026 | BD14: 23 | BE14: JEP | BI14: =(AX14+AZ14+BA14)-(BD14+BG14) -> 0 | BJ14: C0499 | BK14: 23 | BM14: 46161 | BT14: =(BI14+BK14+BL14)-(BO14+BR14) -> 23
A15: 023 | B15: LEON PAREDES ROSA ESPERANZA | C15: 172.18.1.6 | D15: ACTIVO | E15: F | G15: 0107040628 | H15: SAYAUSI | I15: NO | J15: SAN MIGUEL - LA HERMITA | K15: rosaleon5681@gmail.com | L15: 099 986 9789 | N15: 44534 | O15: 100M/100M | P15: GRATIS | Q15: 0 | S15: 17.25 | U15: 46046 | V15: 46051 | W15: 17.25 | X15: JEP | AB15: =S15+T15-W15-Z15 -> 0 | AC15: SIN FACTURA | AD15: 17.25 | AF15: 46077 | AG15: 46079 | AH15: 17.25 | AI15: JEP | AM15: =(AB15+AD15+AE15)-(AH15+AK15) -> 0 | AN15: SIN FACTURA | AO15: 17.25 | AQ15: 46105 | AR15: 18/3/2026 | AS15: 17.25 | AT15: Pichincha | AX15: =(AM15+AO15+AP15)-(AS15+AV15) -> 0 | AY15: SIN FACTURA | AZ15: 17.25 | BB15: 46136 | BC15: 20/4/2026 | BD15: 17.25 | BE15: JEP | BI15: =(AX15+AZ15+BA15)-(BD15+BG15) -> 0 | BK15: 17.25 | BM15: 46166 | BT15: =(BI15+BK15+BL15)-(BO15+BR15) -> 17.25
A16: 024 | B16: SANCHEZ CONDO MILTON BOLIVAR | C16: 172.18.2.19 | D16: INACTIVO | G16: 0703816272 | H16: SAYAUSI | I16: SI | J16: ORDOÑEZ LAZO FRENTE A LA BOMBA PRIMAX | K16: miltonbolivarsanchezcondo@gmail.com | L16: 0991340276 0968925246 | N16: 04/12/2021 | O16: 100M/100M | P16: GRATIS | Q16: 0 | AB16: =S16+T16-W16-Z16 -> 0 | AC16: SIN FACTURA | AM16: =(AB16+AD16+AE16)-(AH16+AK16) -> 0 | AN16: SIN FACTURA | AX16: =(AM16+AO16+AP16)-(AS16+AV16) -> 0 | AY16: SIN FACTURA | BI16: =(AX16+AZ16+BA16)-(BD16+BG16) -> 0 | BT16: =(BI16+BK16+BL16)-(BO16+BR16) -> 0
A17: 027 | B17: LEON PINTADO JOSE MIGUEL | C17: 172.18.1.56 | D17: ACTIVO | E17: M | G17: 0101814556 | H17: SAYAUSI | I17: NO | J17: SECTOR LA HERMITA | L17: 0988570402 0968739394 | N17: 44560 | O17: 650M/650M | P17: GRATIS | Q17: 0 | S17: 25 | U17: 46041 | V17: 46048 | W17: 25 | X17: Pichincha | AB17: =S17+T17-W17-Z17 -> 0 | AC17: SIN FACTURA | AD17: 25 | AF17: 46072 | AG17: 46075 | AH17: 25 | AI17: Pichincha | AJ17: 130637 | AM17: =(AB17+AD17+AE17)-(AH17+AK17) -> 0 | AN17: C0403 | AO17: 25 | AQ17: 46100 | AR17: 25/3/2026 | AS17: 25 | AT17: Pichincha | AX17: =(AM17+AO17+AP17)-(AS17+AV17) -> 0 | AY17: SIN FACTURA | AZ17: 25 | BB17: 46131 | BC17: 20/4/2026 | BD17: 25 | BE17: Pichincha | BF17: 142088 | BI17: =(AX17+AZ17+BA17)-(BD17+BG17) -> 0 | BK17: 25 | BM17: 46161 | BT17: =(BI17+BK17+BL17)-(BO17+BR17) -> 25
A18: 028 | B18: BARRIONUEVO FERNANDEZ FANNY SUSANA | C18: 172.18.2.21 | D18: ACTIVO | E18: ESTA EN EL CHAT | F18: 24 | G18: 1203804750 | H18: SAYAUSI | I18: NO | J18: SECTOR QUINTA CARMITA | K18: fernandezsusy052@gmail.com | L18: 0992051025 0969063324 0989454709 0985313311 | M18: 28safannyb | N18: 46081 | O18: 650M/650M | P18: GRATIS | Q18: -6 | S18: 23 | T18: 0 | U18: 46031 | V18: 46174 | W18: 23 | X18: JEP | AB18: =Q18+S18+T18-W18-Z18 -> -6 | AC18: C0363 | AD18: 23 | AE18: 0 | AF18: 46062 | AG18: 46058 | AH18: 23 | AI18: JEP | AM18: =(AB18+AD18+AE18)-(AH18+AK18) -> -6 | AN18: C0411 | AO18: 23 | AP18: 0 | AQ18: 46090 | AR18: 4/3/2026 | AS18: 23 | AT18: Pichincha | AX18: =(AM18+AO18+AP18)-(AS18+AV18) -> -6 | AY18: C0456 | AZ18: 23 | BA18: 0 | BB18: 46121 | BC18: 7/4/2026 | BD18: 23 | BE18: Pichincha | BI18: =(AX18+AZ18+BA18)-(BD18+BG18) -> -6 | BJ18: C0500 | BK18: 23 | BL18: 0 | BM18: 46151 | BT18: =(BI18+BK18+BL18)-(BO18+BR18) -> 17
A19: 029 | B19: MOROCHO LEON ANGELA ANDREA | C19: 172.18.1.9 | D19: ACTIVO | E19: F | F19: 24 | G19: 0107166399 | H19: SAYAUSI | I19: NO | J19: SAN MIGUEL - SECTOR LA HERMITA | K19: morochoangela704@gmail.com | L19: 0991151608 0990222192 0994631432 | N19: 45503 | O19: 650M/650M | P19: GRATIS | Q19: 0 | S19: 23 | U19: 46031 | V19: 46038 | W19: 23 | X19: Pichincha | Y19: 120478 | AB19: =S19+T19-W19-Z19 -> 0 | AC19: C0364 | AD19: 23 | AF19: 46062 | AG19: 46067 | AH19: 23 | AI19: Pichincha | AJ19: 128538 | AM19: =(AB19+AD19+AE19)-(AH19+AK19) -> 0 | AN19: C0412 | AO19: 23 | AQ19: 46090 | AR19: 18/3/2026 | AS19: 23 | AT19: Pichincha | AU19: 137514 | AX19: =(AM19+AO19+AP19)-(AS19+AV19) -> 0 | AY19: C0457 | AZ19: 23 | BB19: 46121 | BC19: 19/4/2026 | BD19: 23 | BE19: Pichincha | BI19: =(AX19+AZ19+BA19)-(BD19+BG19) -> 0 | BJ19: C0501 | BK19: 23 | BM19: 46151 | BT19: =(BI19+BK19+BL19)-(BO19+BR19) -> 23
A20: 031 | B20: ROBLES PERALTA LUIS ALBERTO | C20: 172.18.2.22 | D20: INACTIVO | E20: M | G20: 0940305378 | H20: SAYAUSI | I20: SI | J20: ORDOÑEZ LAZO Y HIERBA LUISA | K20: ortizjenny716@gmail.com | L20: 0985621316 0992136760 | N20: 44957 | O20: 650M/650M | P20: GRATIS | Q20: 0 | AB20: =S20+T20-W20-Z20 -> 0 | AC20: SIN FACTURA | AM20: =(AB20+AD20+AE20)-(AH20+AK20) -> 0 | AN20: SIN FACTURA | AX20: =(AM20+AO20+AP20)-(AS20+AV20) -> 0 | AY20: SIN FACTURA | BI20: =(AX20+AZ20+BA20)-(BD20+BG20) -> 0 | BT20: =(BI20+BK20+BL20)-(BO20+BR20) -> 0
A21: 032 | B21: MUÑOZ ORTEGA JUAN ESTEBAN | C21: 172.18.4.3 | D21: ACTIVO | E21: F | G21: 0101866556 | H21: SAYAUSI | I21: NO | J21: LA LIBERTAD SECTOR LA PIEDRA GRANDE | K21: jmunoz@cdazuay.com | L21: 0994922373 0997012335 | M21: 32samunozj | N21: 44569 | O21: 650M/650M | P21: 20 | Q21: 0 | S21: 23 | T21: 0 | U21: 46041 | V21: 46043 | W21: 23 | X21: Pichincha | AB21: =S21+T21-W21-Z21 -> 0 | AC21: C0365 | AD21: 23 | AE21: 0 | AF21: 46072 | AG21: 46072 | AH21: 23 | AI21: Pichincha | AJ21: 129772 | AM21: =(AB21+AD21+AE21)-(AH21+AK21) -> 0 | AN21: C0413 | AO21: 23 | AP21: 0 | AQ21: 46100 | AR21: 24/3/2026 | AS21: 23 | AT21: Pichincha | AU21: 138504 | AX21: =(AM21+AO21+AP21)-(AS21+AV21) -> 0 | AY21: C0458 | AZ21: 23 | BA21: 0 | BB21: 46131 | BC21: 23/4/2026 | BD21: 23 | BE21: Pichincha | BI21: =(AX21+AZ21+BA21)-(BD21+BG21) -> 0 | BJ21: C0502 | BK21: 23 | BL21: 0 | BM21: 46161 | BT21: =(BI21+BK21+BL21)-(BO21+BR21) -> 23
A22: 033 | B22: TENEPAGUAY PULLA MARIA ISABEL | C22: 172.18.1.12 | D22: ACTIVO | E22: F | G22: 0103343687 | H22: SAYAUSI | I22: NO | J22: SUBIDA A SAN MIGUEL SECTOR IGLESIA NUEVA | K22: isabeltenempaguay@gmail.com | L22: 0982780021 0991891662 0998871453 | N22: 44579 | O22: 100M/100M | P22: 35 | Q22: -5.03 | S22: 17.25 | U22: 46031 | V22: 46031 | W22: 18.25 | X22: JEP | AB22: =Q22+S22+T22-W22-Z22 -> -6.03 | AC22: SIN FACTURA | AD22: 17.25 | AF22: 46062 | AG22: 46062 | AH22: 18.25 | AI22: JEP | AM22: =(AB22+AD22+AE22)-(AH22+AK22) -> -7.03 | AN22: SIN FACTURA | AO22: 17.25 | AQ22: 46090 | AR22: 7/3/2026 | AS22: 17 | AT22: JEP | AX22: =(AM22+AO22+AP22)-(AS22+AV22) -> -6.78 | AY22: SIN FACTURA | AZ22: 17.25 | BB22: 46121 | BC22: 7/4/2026 | BD22: 17.52 | BE22: JEP | BI22: =(AX22+AZ22+BA22)-(BD22+BG22) -> -7.05 | BK22: 17.25 | BM22: 46151 | BT22: =(BI22+BK22+BL22)-(BO22+BR22) -> 10.2
A23: 034 | B23: BERMEO SANGURIMA MANUELA BEATRIZ | C23: 172.18.1.13 | D23: ACTIVO | E23: F | G23: 0102236015 | H23: SAYAUSI | I23: NO | J23: SAN MIGUEL SECTOR LA HERMITA | L23: 0997060665 0984939313 | N23: 44579 | O23: 100M/100M | P23: GRATIS | Q23: 0 | S23: 17.25 | U23: 46041 | V23: 46034 | W23: 17.25 | X23: Pichincha | Y23: 119415 | AB23: =S23+T23-W23-Z23 -> 0 | AC23: C0353 | AD23: 17.25 | AF23: 46072 | AG23: 46075 | AH23: 17.25 | AI23: Pichincha | AJ23: 131108 | AM23: =(AB23+AD23+AE23)-(AH23+AK23) -> 0 | AN23: C0385 | AO23: 17.25 | AQ23: 46100 | AR23: 18/3/2026 | AS23: 17.25 | AT23: Pichincha | AU23: 137516 | AX23: =(AM23+AO23+AP23)-(AS23+AV23) -> 0 | AY23: C0435 | AZ23: 17.25 | BB23: 46131 | BC23: 20/4/2026 | BD23: 17.25 | BE23: Pichincha | BI23: =(AX23+AZ23+BA23)-(BD23+BG23) -> 0 | BJ23: C02734 | BK23: 17.25 | BM23: 46161 | BT23: =(BI23+BK23+BL23)-(BO23+BR23) -> 17.25
